<?xml version="1.0" encoding="utf-8"?>
<robot name="s2_v1">
  <link name="world"/>
  <link name="base_link">
    <inertial>
      <origin xyz="-0.063865 -0.00011351 0.010653" rpy="0 0 0"/>
      <mass value="6.10570002"/>
      <inertia ixx="0.05624788" ixy="0.0000729" ixz="0.00443191" iyy="0.02883305" iyz="0.00013039" izz="0.07296708"/>
    </inertial>
    <visual name="mesh">
      <geometry>
        <mesh filename="./meshes/mesh.obj"/>
      </geometry>
    </visual>
    <visual name="CameraModel">
      <geometry>
        <mesh filename="./meshes/CameraModel.obj"/>
      </geometry>
    </visual>
    <visual name="base_01">
      <geometry>
        <mesh filename="./meshes/base_01.obj"/>
      </geometry>
    </visual>
  </link>
  <link name="L_hip_roll_link">
    <inertial>
      <origin xyz="0.0092362 0.00068462 -0.0076246" rpy="0 0 0"/>
      <mass value="1.3211"/>
      <inertia ixx="0.00186663" ixy="-0.00000612" ixz="0.00009625" iyy="0.00173512" iyz="-0.00003425" izz="0.00116355"/>
    </inertial>
    <visual name="mesh">
      <origin xyz="0 0 0" rpy="0 -0.00000012 0"/>
      <geometry>
        <mesh filename="./meshes/mesh_1.obj"/>
      </geometry>
    </visual>
    <visual name="L_hip_roll_01">
      <geometry>
        <mesh filename="./meshes/L_hip_roll_01.obj"/>
      </geometry>
    </visual>
  </link>
  <link name="R_hip_roll_link">
    <inertial>
      <origin xyz="0.0092362 0.00068462 -0.0076246" rpy="0 0 0"/>
      <mass value="1.3211"/>
      <inertia ixx="0.00186663" ixy="-0.00000612" ixz="0.00009625" iyy="0.00173512" iyz="-0.00003425" izz="0.00116355"/>
    </inertial>
    <visual name="mesh">
      <origin xyz="0 0 0" rpy="0 -0.00000012 0"/>
      <geometry>
        <mesh filename="./meshes/mesh_2.obj"/>
      </geometry>
    </visual>
    <visual name="L_hip_roll_01">
      <geometry>
        <mesh filename="./meshes/L_hip_roll_01_1.obj"/>
      </geometry>
    </visual>
  </link>
  <link name="waist_yaw_link">
    <inertial>
      <origin xyz="-0.00019894 -0.0096767 0.027108" rpy="0 0 0"/>
      <mass value="0.51683998"/>
      <inertia ixx="0.00171941" ixy="-0.00000234" ixz="-0.00000885" iyy="0.00108361" iyz="0.000065" izz="0.00138787"/>
    </inertial>
    <visual name="mesh">
      <geometry>
        <mesh filename="./meshes/mesh_3.obj"/>
      </geometry>
    </visual>
    <visual name="waist_yaw_01">
      <geometry>
        <mesh filename="./meshes/waist_yaw_01.obj"/>
      </geometry>
    </visual>
  </link>
  <link name="L_hip_yaw_link">
    <inertial>
      <origin xyz="0.00023965 0.0039636 0.11569" rpy="0 0 0"/>
      <mass value="2.28909993"/>
      <inertia ixx="0.00430441" ixy="-0.00000501" ixz="0.00000866" iyy="0.0048929" iyz="0.000051" izz="0.00362769"/>
    </inertial>
    <visual name="mesh">
      <origin xyz="0 0 0" rpy="0 -0.00000006 0"/>
      <geometry>
        <mesh filename="./meshes/mesh_4.obj"/>
      </geometry>
    </visual>
    <visual name="hip_yaw_01">
      <geometry>
        <mesh filename="./meshes/hip_yaw_01.obj"/>
      </geometry>
    </visual>
  </link>
  <link name="R_hip_yaw_link">
    <inertial>
      <origin xyz="0.00023965 0.0039636 0.11569" rpy="0 0 0"/>
      <mass value="2.28909993"/>
      <inertia ixx="0.00430441" ixy="-0.00000501" ixz="0.00000866" iyy="0.0048929" iyz="0.000051" izz="0.00362769"/>
    </inertial>
    <visual name="mesh">
      <origin xyz="0 0 0" rpy="0 -0.00000006 0"/>
      <geometry>
        <mesh filename="./meshes/mesh_5.obj"/>
      </geometry>
    </visual>
    <visual name="hip_yaw_01">
      <geometry>
        <mesh filename="./meshes/hip_yaw_01_1.obj"/>
      </geometry>
    </visual>
  </link>
  <link name="waist_pitch_link">
    <inertial>
      <origin xyz="-0.017372 0.20542 -0.0021071" rpy="0 0 0"/>
      <mass value="24.18600082"/>
      <inertia ixx="0.52256693" ixy="-0.01202184" ixz="-0.00198925" iyy="0.20002347" iyz="0.00591645" izz="0.46707963"/>
    </inertial>
    <visual name="mesh">
      <origin xyz="0 0 0" rpy="0.00000003 0 0"/>
      <geometry>
        <mesh filename="./meshes/mesh_6.obj"/>
      </geometry>
    </visual>
    <visual name="box">
      <origin xyz="0 0.2 0.00000001" rpy="0.00000003 0 0"/>
      <geometry>
        <box size="1 1 1"/>
      </geometry>
    </visual>
    <visual name="CameraModel">
      <geometry>
        <mesh filename="./meshes/CameraModel_1.obj"/>
      </geometry>
    </visual>
    <visual name="waist_pitch_01">
      <geometry>
        <mesh filename="./meshes/waist_pitch_01.obj"/>
      </geometry>
    </visual>
    <collision name="box">
      <origin xyz="0 0.2 0.00000001" rpy="0.00000003 0 0"/>
      <geometry>
        <box size="1 1 1"/>
      </geometry>
    </collision>
  </link>
  <link name="L_hip_pitch_link">
    <inertial>
      <origin xyz="0.0018469 -0.1559 -0.0026939" rpy="0 0 0"/>
      <mass value="4.15059996"/>
      <inertia ixx="0.04292096" ixy="-0.00182136" ixz="0.00006136" iyy="0.00998539" iyz="0.00113685" izz="0.04278405"/>
    </inertial>
    <visual name="mesh">
      <origin xyz="0 0 -0" rpy="-0.00000015 0 0"/>
      <geometry>
        <mesh filename="./meshes/mesh_7.obj"/>
      </geometry>
    </visual>
    <visual name="cylinder">
      <origin xyz="-0.0054 -0.1728 -0.00119998" rpy="1.57079975 0 0"/>
      <geometry>
        <cylinder radius="0.0878" length="0.30000001"/>
      </geometry>
    </visual>
    <visual name="L_hip_pitch_01">
      <geometry>
        <mesh filename="./meshes/L_hip_pitch_01.obj"/>
      </geometry>
    </visual>
    <collision name="cylinder">
      <origin xyz="-0.0054 -0.1728 -0.00119998" rpy="1.57079975 0 0"/>
      <geometry>
        <cylinder radius="0.0878" length="0.30000001"/>
      </geometry>
    </collision>
  </link>
  <link name="R_hip_pitch_link">
    <inertial>
      <origin xyz="0.0015213 -0.15561 0.0027829" rpy="0 0 0"/>
      <mass value="4.15579987"/>
      <inertia ixx="0.04288498" ixy="-0.00181276" ixz="-0.00005203" iyy="0.01000207" iyz="-0.00128118" izz="0.04270595"/>
    </inertial>
    <visual name="mesh">
      <origin xyz="0 0 -0" rpy="-0.00000015 0 0"/>
      <geometry>
        <mesh filename="./meshes/mesh_8.obj"/>
      </geometry>
    </visual>
    <visual name="cylinder">
      <origin xyz="-0.0054 -0.1728 -0.00119998" rpy="1.57079975 0 0"/>
      <geometry>
        <cylinder radius="0.0878" length="0.30000001"/>
      </geometry>
    </visual>
    <visual name="R_hip_pitch_01">
      <geometry>
        <mesh filename="./meshes/R_hip_pitch_01.obj"/>
      </geometry>
    </visual>
    <collision name="cylinder">
      <origin xyz="-0.0054 -0.1728 -0.00119998" rpy="1.57079975 0 0"/>
      <geometry>
        <cylinder radius="0.0878" length="0.30000001"/>
      </geometry>
    </collision>
  </link>
  <link name="torso_link">
    <inertial>
      <mass value="0.0001"/>
      <inertia ixx="0" ixy="0" ixz="0" iyy="0" iyz="0" izz="0"/>
    </inertial>
  </link>
  <link name="L_knee_pitch_link">
    <inertial>
      <origin xyz="-0.0010047 -0.15955 0.0010045" rpy="0 0 0"/>
      <mass value="3.82690001"/>
      <inertia ixx="0.0340684" ixy="0.00089916" ixz="0.0000617" iyy="0.00486482" iyz="0.00007442" izz="0.03481659"/>
    </inertial>
    <visual name="mesh">
      <origin xyz="0 -0.0000001 0" rpy="0 0 0"/>
      <geometry>
        <mesh filename="./meshes/mesh_9.obj"/>
      </geometry>
    </visual>
    <visual name="cylinder">
      <origin xyz="0.0048 -0.1752001 -0.0029" rpy="1.5707999 0 0"/>
      <geometry>
        <cylinder radius="0.06165" length="0.30000001"/>
      </geometry>
    </visual>
    <visual name="L_knee_pitch_01">
      <geometry>
        <mesh filename="./meshes/L_knee_pitch_01.obj"/>
      </geometry>
    </visual>
    <collision name="cylinder">
      <origin xyz="0.0048 -0.1752001 -0.0029" rpy="1.5707999 0 0"/>
      <geometry>
        <cylinder radius="0.06165" length="0.30000001"/>
      </geometry>
    </collision>
  </link>
  <link name="R_knee_pitch_link">
    <inertial>
      <origin xyz="-0.0010047 -0.15955 0.0010045" rpy="0 0 0"/>
      <mass value="3.82690001"/>
      <inertia ixx="0.0340684" ixy="0.00089916" ixz="0.0000617" iyy="0.00486482" iyz="0.00007442" izz="0.03481659"/>
    </inertial>
    <visual name="mesh">
      <origin xyz="0 -0.0000001 0" rpy="0 0 0"/>
      <geometry>
        <mesh filename="./meshes/mesh_10.obj"/>
      </geometry>
    </visual>
    <visual name="cylinder">
      <origin xyz="0.0048 -0.1752001 -0.0029" rpy="1.5707999 0 0"/>
      <geometry>
        <cylinder radius="0.06165" length="0.30000001"/>
      </geometry>
    </visual>
    <visual name="R_knee_pitch_01">
      <geometry>
        <mesh filename="./meshes/R_knee_pitch_01.obj"/>
      </geometry>
    </visual>
    <collision name="cylinder">
      <origin xyz="0.0048 -0.1752001 -0.0029" rpy="1.5707999 0 0"/>
      <geometry>
        <cylinder radius="0.06165" length="0.30000001"/>
      </geometry>
    </collision>
  </link>
  <link name="L_shoulder_pitch_link">
    <inertial>
      <origin xyz="0.000221 -0.0050932 -0.05263" rpy="0 0 0"/>
      <mass value="0.98146999"/>
      <inertia ixx="0.00117593" ixy="0.00000452" ixz="0.00000012" iyy="0.00112367" iyz="0.00003134" izz="0.00090042"/>
    </inertial>
    <visual name="mesh">
      <origin xyz="0 0 0" rpy="-0.00000005 0.00000009 -0.00000003"/>
      <geometry>
        <mesh filename="./meshes/mesh_11.obj"/>
      </geometry>
    </visual>
    <visual name="L_should_pitch_01">
      <geometry>
        <mesh filename="./meshes/L_should_pitch_01.obj"/>
      </geometry>
    </visual>
  </link>
  <link name="R_shoulder_pitch_link">
    <inertial>
      <origin xyz="-0.0000887 0.0050444 -0.052623" rpy="0 0 0"/>
      <mass value="0.98272997"/>
      <inertia ixx="0.00117764" ixy="0.00000672" ixz="0.00000743" iyy="0.00112459" iyz="-0.00003068" izz="0.00090284"/>
    </inertial>
    <visual name="mesh">
      <origin xyz="-0 0 -0" rpy="-0.00000004 -0.00000008 -0.00000005"/>
      <geometry>
        <mesh filename="./meshes/mesh_12.obj"/>
      </geometry>
    </visual>
    <visual name="should_pitch_01">
      <geometry>
        <mesh filename="./meshes/should_pitch_01.obj"/>
      </geometry>
    </visual>
  </link>
  <link name="head_yaw_link">
    <inertial>
      <origin xyz="0.00023349 -0.0000398 0.023081" rpy="0 0 0"/>
      <mass value="0.21952"/>
      <inertia ixx="0.00008121" ixy="-0.00000095" ixz="-0.00000014" iyy="0.0000629" iyz="-0.0000038" izz="0.00007629"/>
    </inertial>
    <visual name="mesh">
      <origin xyz="0 0 -0.00000001" rpy="0 0 0"/>
      <geometry>
        <mesh filename="./meshes/mesh_13.obj"/>
      </geometry>
    </visual>
  </link>
  <link name="L_ankle_pitch_link">
    <inertial>
      <mass value="0.065914"/>
      <inertia ixx="0.0000109" ixy="0.00000005" ixz="0" iyy="0.0000184" iyz="0" izz="0.0000109"/>
    </inertial>
    <visual name="mesh">
      <origin xyz="0 -0.00000012 0" rpy="0 0 0"/>
      <geometry>
        <mesh filename="./meshes/mesh_14.obj"/>
      </geometry>
    </visual>
    <visual name="ankle_pitch_01">
      <geometry>
        <mesh filename="./meshes/ankle_pitch_01.obj"/>
      </geometry>
    </visual>
  </link>
  <link name="R_ankle_pitch_link">
    <inertial>
      <mass value="0.065914"/>
      <inertia ixx="0.0000109" ixy="0" ixz="0" iyy="0.0000184" iyz="0" izz="0.0000109"/>
    </inertial>
    <visual name="mesh">
      <origin xyz="0 -0.00000012 0" rpy="0 0 0"/>
      <geometry>
        <mesh filename="./meshes/mesh_15.obj"/>
      </geometry>
    </visual>
    <visual name="ankle_pitch_01">
      <geometry>
        <mesh filename="./meshes/ankle_pitch_01_1.obj"/>
      </geometry>
    </visual>
  </link>
  <link name="L_shoulder_roll_link">
    <inertial>
      <origin xyz="-0.036346 0.0019751 -0.0052697" rpy="0 0 0"/>
      <mass value="0.53956997"/>
      <inertia ixx="0.00123013" ixy="0.00001644" ixz="-0.00010584" iyy="0.00189124" iyz="0.00002348" izz="0.00143043"/>
    </inertial>
    <visual name="mesh">
      <origin xyz="-0.00000001 -0 0" rpy="0.00000009 0.00000011 -0.00000004"/>
      <geometry>
        <mesh filename="./meshes/mesh_16.obj"/>
      </geometry>
    </visual>
    <visual name="L_should_roll_01">
      <geometry>
        <mesh filename="./meshes/L_should_roll_01.obj"/>
      </geometry>
    </visual>
  </link>
  <link name="R_shoulder_roll_link">
    <inertial>
      <origin xyz="-0.036091 0.0019662 0.0053449" rpy="0 0 0"/>
      <mass value="0.54339999"/>
      <inertia ixx="0.00124573" ixy="0.00001585" ixz="0.0001079" iyy="0.00191175" iyz="-0.00002356" izz="0.00143742"/>
    </inertial>
    <visual name="mesh">
      <origin xyz="0.00000001 -0 0" rpy="0.0000001 0.00000003 0"/>
      <geometry>
        <mesh filename="./meshes/mesh_17.obj"/>
      </geometry>
    </visual>
    <visual name="should_roll_01">
      <geometry>
        <mesh filename="./meshes/should_roll_01.obj"/>
      </geometry>
    </visual>
  </link>
  <link name="head_pitch_link">
    <inertial>
      <origin xyz="0.040566 0.1025 -0.00026038" rpy="0 0 0"/>
      <mass value="1.06900001"/>
      <inertia ixx="0.00474143" ixy="-0.00032914" ixz="0.00005925" iyy="0.00450668" iyz="0.00005056" izz="0.00518109"/>
    </inertial>
    <visual name="mesh">
      <origin xyz="0 -0.00000002 0" rpy="-0.00000012 0 0"/>
      <geometry>
        <mesh filename="./meshes/mesh_18.obj"/>
      </geometry>
    </visual>
    <visual name="CameraModel">
      <geometry>
        <mesh filename="./meshes/CameraModel_2.obj"/>
      </geometry>
    </visual>
    <visual name="CameraModel">
      <geometry>
        <mesh filename="./meshes/CameraModel_3.obj"/>
      </geometry>
    </visual>
    <visual name="CameraModel">
      <geometry>
        <mesh filename="./meshes/CameraModel_4.obj"/>
      </geometry>
    </visual>
    <visual name="CameraModel">
      <geometry>
        <mesh filename="./meshes/CameraModel_5.obj"/>
      </geometry>
    </visual>
    <visual name="head_pitch_01">
      <geometry>
        <mesh filename="./meshes/head_pitch_01.obj"/>
      </geometry>
    </visual>
  </link>
  <link name="L_ankle_roll_link">
    <inertial>
      <origin xyz="-0.030998 -0.000273 0.023974" rpy="0 0 0"/>
      <mass value="0.78306001"/>
      <inertia ixx="0.00326839" ixy="0.0000032" ixz="-0.00016304" iyy="0.00288051" iyz="0.00000652" izz="0.00070111"/>
    </inertial>
    <visual name="mesh">
      <origin xyz="0 0 0" rpy="-0.00000004 -0.00000011 0.00000016"/>
      <geometry>
        <mesh filename="./meshes/mesh_19.obj"/>
      </geometry>
    </visual>
    <visual name="box">
      <origin xyz="-0.03400001 -0 0.0491" rpy="-0.00000005 -0.00000009 0.00000015"/>
      <geometry>
        <box size="1 1 1"/>
      </geometry>
    </visual>
    <visual name="ankle_roll_01">
      <geometry>
        <mesh filename="./meshes/ankle_roll_01.obj"/>
      </geometry>
    </visual>
    <collision name="box">
      <origin xyz="-0.03400001 -0 0.0491" rpy="-0.00000005 -0.00000009 0.00000015"/>
      <geometry>
        <box size="1 1 1"/>
      </geometry>
    </collision>
  </link>
  <link name="R_ankle_roll_link">
    <inertial>
      <origin xyz="-0.030998 0.00026566 0.023951" rpy="0 0 0"/>
      <mass value="0.78315997"/>
      <inertia ixx="0.00326859" ixy="-0.00000318" ixz="-0.00016404" iyy="0.00288051" iyz="-0.00000625" izz="0.00070131"/>
    </inertial>
    <visual name="mesh">
      <origin xyz="0 0 0" rpy="-0.00000004 -0.00000011 0.00000016"/>
      <geometry>
        <mesh filename="./meshes/mesh_20.obj"/>
      </geometry>
    </visual>
    <visual name="box">
      <origin xyz="-0.03400001 -0 0.0491" rpy="-0.00000005 -0.00000009 0.00000015"/>
      <geometry>
        <box size="1 1 1"/>
      </geometry>
    </visual>
    <visual name="ankle_roll_01">
      <geometry>
        <mesh filename="./meshes/ankle_roll_01_1.obj"/>
      </geometry>
    </visual>
    <collision name="box">
      <origin xyz="-0.03400001 -0 0.0491" rpy="-0.00000005 -0.00000009 0.00000015"/>
      <geometry>
        <box size="1 1 1"/>
      </geometry>
    </collision>
  </link>
  <link name="L_shoulder_yaw_link">
    <inertial>
      <origin xyz="-0.00899 0.00278 0.1286" rpy="0 0 0"/>
      <mass value="1.99759996"/>
      <inertia ixx="0.0156648" ixy="0.00005796" ixz="-0.00152637" iyy="0.01575917" iyz="0.00055798" izz="0.00210573"/>
    </inertial>
    <visual name="mesh">
      <origin xyz="0 -0 0.00000001" rpy="-0.00000006 0.00000004 -0.00000005"/>
      <geometry>
        <mesh filename="./meshes/mesh_21.obj"/>
      </geometry>
    </visual>
    <visual name="L_should_yaw_01">
      <geometry>
        <mesh filename="./meshes/L_should_yaw_01.obj"/>
      </geometry>
    </visual>
  </link>
  <link name="R_shoulder_yaw_link">
    <inertial>
      <origin xyz="-0.0090557 -0.0029797 0.12863" rpy="0 0 0"/>
      <mass value="1.99650002"/>
      <inertia ixx="0.01563356" ixy="-0.0000444" ixz="-0.00160418" iyy="0.01575846" iyz="-0.00034152" izz="0.00210927"/>
    </inertial>
    <visual name="mesh">
      <origin xyz="0 0 -0.00000001" rpy="-0.00000002 -0.00000008 -0.00000003"/>
      <geometry>
        <mesh filename="./meshes/mesh_22.obj"/>
      </geometry>
    </visual>
    <visual name="should_yaw_01">
      <geometry>
        <mesh filename="./meshes/should_yaw_01.obj"/>
      </geometry>
    </visual>
  </link>
  <link name="L_elbow_roll_link">
    <inertial>
      <origin xyz="0.0085304 -0.05741 0.00089275" rpy="0 0 0"/>
      <mass value="0.66750002"/>
      <inertia ixx="0.00253829" ixy="-0.00030623" ixz="0.00001255" iyy="0.00139505" iyz="0.00003069" izz="0.00220517"/>
    </inertial>
    <visual name="mesh">
      <origin xyz="-0 -0.00000001 -0" rpy="-0.00000002 -0.0000001 0.00000001"/>
      <geometry>
        <mesh filename="./meshes/mesh_23.obj"/>
      </geometry>
    </visual>
    <visual name="L_elbow_roll_01">
      <geometry>
        <mesh filename="./meshes/L_elbow_roll_01.obj"/>
      </geometry>
    </visual>
  </link>
  <link name="R_elbow_roll_link">
    <inertial>
      <origin xyz="0.0083606 -0.0579 -0.00065816" rpy="0 0 0"/>
      <mass value="0.68336999"/>
      <inertia ixx="0.00259972" ixy="-0.00029762" ixz="-0.00001004" iyy="0.00143256" iyz="-0.0000238" izz="0.00224882"/>
    </inertial>
    <visual name="mesh">
      <origin xyz="0 0 -0" rpy="-0.00000001 0.00000005 -0.00000002"/>
      <geometry>
        <mesh filename="./meshes/mesh_24.obj"/>
      </geometry>
    </visual>
    <visual name="L_elbow_roll_01">
      <geometry>
        <mesh filename="./meshes/L_elbow_roll_01_1.obj"/>
      </geometry>
    </visual>
  </link>
  <link name="L_elbow_yaw_link">
    <inertial>
      <origin xyz="0.00097407 0.00017933 0.045777" rpy="0 0 0"/>
      <mass value="0.87457001"/>
      <inertia ixx="0.0014384" ixy="-0.00000383" ixz="0.00005221" iyy="0.0016363" iyz="-0.00000002" izz="0.00087583"/>
    </inertial>
    <visual name="mesh">
      <origin xyz="-0.00000001 -0.00000001 0.00000002" rpy="0.00000003 0.00000006 -0.0000001"/>
      <geometry>
        <mesh filename="./meshes/mesh_25.obj"/>
      </geometry>
    </visual>
    <visual name="L_elbow_yaw_01">
      <geometry>
        <mesh filename="./meshes/L_elbow_yaw_01.obj"/>
      </geometry>
    </visual>
  </link>
  <link name="R_elbow_yaw_link">
    <inertial>
      <origin xyz="-0.00097407 -0.00017922 0.045777" rpy="0 0 0"/>
      <mass value="0.87457001"/>
      <inertia ixx="0.0014384" ixy="-0.00000383" ixz="-0.00005221" iyy="0.00164" iyz="0.00000005" izz="0.00087583"/>
    </inertial>
    <visual name="mesh">
      <origin xyz="-0 -0.00000001 0" rpy="-0.00000008 -0.00000002 -0.00000002"/>
      <geometry>
        <mesh filename="./meshes/mesh_26.obj"/>
      </geometry>
    </visual>
    <visual name="elbow_yaw_01">
      <geometry>
        <mesh filename="./meshes/elbow_yaw_01.obj"/>
      </geometry>
    </visual>
  </link>
  <link name="L_wrist_pitch_link">
    <inertial>
      <origin xyz="-0.038445 -0.0048559 -0.0047721" rpy="0 0 0"/>
      <mass value="1.31449997"/>
      <inertia ixx="0.00090047" ixy="0.00029445" ixz="-0.0001139" iyy="0.00271051" iyz="0.0000142" izz="0.00275658"/>
    </inertial>
    <visual name="mesh">
      <origin xyz="0 -0 0.00000001" rpy="-0.00000013 0.00000018 -0.00000006"/>
      <geometry>
        <mesh filename="./meshes/mesh_27.obj"/>
      </geometry>
    </visual>
    <visual name="L_wrist_pitch_01">
      <geometry>
        <mesh filename="./meshes/L_wrist_pitch_01.obj"/>
      </geometry>
    </visual>
  </link>
  <link name="R_wrist_pitch_link">
    <inertial>
      <origin xyz="-0.038445 0.0048559 0.0047721" rpy="0 0 0"/>
      <mass value="1.31449997"/>
      <inertia ixx="0.00090047" ixy="-0.00029479" ixz="0.00011416" iyy="0.00271052" iyz="0.00001433" izz="0.00275658"/>
    </inertial>
    <visual name="mesh">
      <origin xyz="-0 0 -0.00000001" rpy="0.00000005 0.00000009 0.00000006"/>
      <geometry>
        <mesh filename="./meshes/mesh_28.obj"/>
      </geometry>
    </visual>
    <visual name="wrist_pitch_01">
      <geometry>
        <mesh filename="./meshes/wrist_pitch_01.obj"/>
      </geometry>
    </visual>
  </link>
  <link name="L_wrist_roll_link">
    <inertial>
      <origin xyz="-0.00000459 0.017056 -0.0007487" rpy="0 0 0"/>
      <mass value="0.1521"/>
      <inertia ixx="0.00027356" ixy="-0" ixz="0.00000002" iyy="0.00021546" iyz="0.00000768" izz="0.00011023"/>
    </inertial>
    <visual name="mesh">
      <origin xyz="0.00000002 0.00000003 0.00000002" rpy="0.00000002 0.00000005 -0.00000031"/>
      <geometry>
        <mesh filename="./meshes/mesh_29.obj"/>
      </geometry>
    </visual>
    <visual name="L_wrist_roll_01">
      <geometry>
        <mesh filename="./meshes/L_wrist_roll_01.obj"/>
      </geometry>
    </visual>
  </link>
  <link name="R_wrist_roll_link">
    <inertial>
      <origin xyz="0.00000463 0.017056 0.0007487" rpy="0 0 0"/>
      <mass value="0.1521"/>
      <inertia ixx="0.00027356" ixy="0" ixz="0.00000002" iyy="0.00021546" iyz="-0.00000768" izz="0.00011023"/>
    </inertial>
    <visual name="mesh">
      <origin xyz="0.00000001 0.00000002 -0.00000001" rpy="0.00000008 -0.00000003 0.00000005"/>
      <geometry>
        <mesh filename="./meshes/mesh_30.obj"/>
      </geometry>
    </visual>
    <visual name="wrist_roll_01">
      <geometry>
        <mesh filename="./meshes/wrist_roll_01.obj"/>
      </geometry>
    </visual>
  </link>
  <link name="L_sixforce_link">
    <inertial>
      <origin xyz="0.00018615 0.00000211 -0.011066" rpy="0 0 0"/>
      <mass value="0.17"/>
      <inertia ixx="0.0000357" ixy="-0.00000022" ixz="0.00000078" iyy="0.0000503" iyz="-0.00000004" izz="0.0000613"/>
    </inertial>
    <visual name="mesh">
      <origin xyz="0.00000004 0.00000001 0.00000001" rpy="0 1.57079601 -0.00000019"/>
      <geometry>
        <mesh filename="./meshes/mesh_31.obj"/>
      </geometry>
    </visual>
    <visual name="mesh_">
      <geometry>
        <mesh filename="./meshes/mesh_.obj"/>
      </geometry>
    </visual>
  </link>
  <link name="R_sixforce_link">
    <inertial>
      <origin xyz="-0.00018615 -0.00000211 -0.011066" rpy="0 0 0"/>
      <mass value="0.17"/>
      <inertia ixx="0.0000357" ixy="-0.00000022" ixz="-0.00000078" iyy="0.0000503" iyz="0.00000004" izz="0.0000613"/>
    </inertial>
    <visual name="mesh">
      <origin xyz="0.00000001 0.00000001 -0.00000001" rpy="0 1.57079617 -0.00000005"/>
      <geometry>
        <mesh filename="./meshes/mesh_32.obj"/>
      </geometry>
    </visual>
    <visual name="mesh_">
      <geometry>
        <mesh filename="./meshes/mesh__1.obj"/>
      </geometry>
    </visual>
  </link>
  <link name="L_hand_base_link">
    <inertial>
      <origin xyz="0.00065934 0.00064662 0.02223161" rpy="0 0 0"/>
      <mass value="0.05238695"/>
      <inertia ixx="0.00001722" ixy="0.00000028" ixz="-0.00000043" iyy="0.00003682" iyz="-0.00000022" izz="0.00004011"/>
    </inertial>
    <visual name="L_thumb_ip_link">
      <origin xyz="-0.09140339 -0.06604652 0.06123286" rpy="1.466094 0.00000542 -2.38934898"/>
      <geometry>
        <mesh filename="./meshes/L_thumb_ip_link.obj"/>
      </geometry>
    </visual>
    <visual name="L_thumb_mpp_link">
      <origin xyz="-0.03664073 -0.01480151 0.06124483" rpy="1.466094 0.00000542 -2.38934898"/>
      <geometry>
        <mesh filename="./meshes/L_thumb_mpp_link.obj"/>
      </geometry>
    </visual>
    <visual name="L_thumb_cmp_link">
      <origin xyz="-0.02860013 -0.00583131 0.05119989" rpy="-3.14159131 0.00000542 -2.38934898"/>
      <geometry>
        <mesh filename="./meshes/L_thumb_cmp_link.obj"/>
      </geometry>
    </visual>
    <visual name="L_index_ip_link">
      <origin xyz="-0.03117955 -0.0084915 0.17975211" rpy="-1.45036277 -1.40292415 -1.6895455"/>
      <geometry>
        <mesh filename="./meshes/L_index_ip_link.obj"/>
      </geometry>
    </visual>
    <visual name="L_index_mpp_link">
      <origin xyz="-0.03041348 -0.00150011 0.14159489" rpy="-1.45982714 -1.3885197 -1.67993446"/>
      <geometry>
        <mesh filename="./meshes/L_index_mpp_link.obj"/>
      </geometry>
    </visual>
    <visual name="L_middle_ip_link">
      <origin xyz="-0.01000059 -0.00849143 0.17996487" rpy="-1.57077037 -1.40167599 -1.57081453"/>
      <geometry>
        <mesh filename="./meshes/L_middle_ip_link.obj"/>
      </geometry>
    </visual>
    <visual name="L_middle_mpp_link">
      <origin xyz="-0.01000048 -0.00150004 0.14179996" rpy="-1.57077208 -1.38961632 -1.57081279"/>
      <geometry>
        <mesh filename="./meshes/L_middle_mpp_link.obj"/>
      </geometry>
    </visual>
    <visual name="L_ring_ip_link">
      <origin xyz="0.01117836 -0.00849135 0.17975227" rpy="-1.69117805 -1.40292506 -1.45208361"/>
      <geometry>
        <mesh filename="./meshes/L_index_ip_link.obj"/>
      </geometry>
    </visual>
    <visual name="L_ring_mpp_link">
      <origin xyz="0.01041252 -0.00149996 0.14159504" rpy="-1.68171769 -1.38852052 -1.46169058"/>
      <geometry>
        <mesh filename="./meshes/L_middle_mpp_link.obj"/>
      </geometry>
    </visual>
    <visual name="L_little_ip_link">
      <origin xyz="0.03234905 -0.00849127 0.17911528" rpy="-1.80829095 -1.39939616 -1.33664781"/>
      <geometry>
        <mesh filename="./meshes/L_little_ip_link.obj"/>
      </geometry>
    </visual>
    <visual name="L_little_mpp_link">
      <origin xyz="0.03081752 -0.00149989 0.14098111" rpy="-1.7900886 -1.3852709 -1.35514344"/>
      <geometry>
        <mesh filename="./meshes/L_little_mpp_link.obj"/>
      </geometry>
    </visual>
    <visual name="L_palm_link">
      <origin xyz="0.00035572 -0.013196 0.099778" rpy="-1.57159818 -1.57079263 -3.14078711"/>
      <geometry>
        <mesh filename="./meshes/L_palm_link.obj"/>
      </geometry>
    </visual>
    <visual name="L_hand_base_link">
      <geometry>
        <mesh filename="./meshes/L_hand_base_link.obj"/>
      </geometry>
    </visual>
    <collision name="L_thumb_ip_link">
      <origin xyz="-0.09140339 -0.06604652 0.06123286" rpy="1.466094 0.00000542 -2.38934898"/>
      <geometry>
        <mesh filename="./meshes/L_thumb_ip_link.obj"/>
      </geometry>
    </collision>
    <collision name="L_thumb_mpp_link">
      <origin xyz="-0.03664073 -0.01480151 0.06124483" rpy="1.466094 0.00000542 -2.38934898"/>
      <geometry>
        <mesh filename="./meshes/L_thumb_mpp_link.obj"/>
      </geometry>
    </collision>
    <collision name="L_thumb_cmp_link">
      <origin xyz="-0.02860013 -0.00583131 0.05119989" rpy="-3.14159131 0.00000542 -2.38934898"/>
      <geometry>
        <mesh filename="./meshes/L_thumb_cmp_link.obj"/>
      </geometry>
    </collision>
    <collision name="L_index_ip_link">
      <origin xyz="-0.03117955 -0.0084915 0.17975211" rpy="-1.45036277 -1.40292415 -1.6895455"/>
      <geometry>
        <mesh filename="./meshes/L_index_ip_link.obj"/>
      </geometry>
    </collision>
    <collision name="L_index_mpp_link">
      <origin xyz="-0.03041348 -0.00150011 0.14159489" rpy="-1.45982714 -1.3885197 -1.67993446"/>
      <geometry>
        <mesh filename="./meshes/L_index_mpp_link.obj"/>
      </geometry>
    </collision>
    <collision name="L_middle_ip_link">
      <origin xyz="-0.01000059 -0.00849143 0.17996487" rpy="-1.57077037 -1.40167599 -1.57081453"/>
      <geometry>
        <mesh filename="./meshes/L_middle_ip_link.obj"/>
      </geometry>
    </collision>
    <collision name="L_middle_mpp_link">
      <origin xyz="-0.01000048 -0.00150004 0.14179996" rpy="-1.57077208 -1.38961632 -1.57081279"/>
      <geometry>
        <mesh filename="./meshes/L_middle_mpp_link.obj"/>
      </geometry>
    </collision>
    <collision name="L_ring_ip_link">
      <origin xyz="0.01117836 -0.00849135 0.17975227" rpy="-1.69117805 -1.40292506 -1.45208361"/>
      <geometry>
        <mesh filename="./meshes/L_index_ip_link.obj"/>
      </geometry>
    </collision>
    <collision name="L_ring_mpp_link">
      <origin xyz="0.01041252 -0.00149996 0.14159504" rpy="-1.68171769 -1.38852052 -1.46169058"/>
      <geometry>
        <mesh filename="./meshes/L_middle_mpp_link.obj"/>
      </geometry>
    </collision>
    <collision name="L_little_ip_link">
      <origin xyz="0.03234905 -0.00849127 0.17911528" rpy="-1.80829095 -1.39939616 -1.33664781"/>
      <geometry>
        <mesh filename="./meshes/L_little_ip_link.obj"/>
      </geometry>
    </collision>
    <collision name="L_little_mpp_link">
      <origin xyz="0.03081752 -0.00149989 0.14098111" rpy="-1.7900886 -1.3852709 -1.35514344"/>
      <geometry>
        <mesh filename="./meshes/L_little_mpp_link.obj"/>
      </geometry>
    </collision>
    <collision name="L_palm_link">
      <origin xyz="0.00035572 -0.013196 0.099778" rpy="-1.57159818 -1.57079263 -3.14078711"/>
      <geometry>
        <mesh filename="./meshes/L_palm_link.obj"/>
      </geometry>
    </collision>
    <collision name="L_hand_base_link">
      <geometry>
        <mesh filename="./meshes/L_hand_base_link.obj"/>
      </geometry>
    </collision>
  </link>
  <link name="R_hand_base_link">
    <inertial>
      <origin xyz="0.00065934 -0.00064662 0.02223161" rpy="0 0 0"/>
      <mass value="0.05238695"/>
      <inertia ixx="0.00001722" ixy="-0.00000028" ixz="-0.00000043" iyy="0.00003682" iyz="0.00000022" izz="0.00004011"/>
    </inertial>
    <visual name="R_thumb_ip_link">
      <origin xyz="0.0921168 -0.06604584 0.06123353" rpy="1.6755038 -0.01185903 -0.75348254"/>
      <geometry>
        <mesh filename="./meshes/R_thumb_ip_link.obj"/>
      </geometry>
    </visual>
    <visual name="R_thumb_mpp_link">
      <origin xyz="0.03735377 -0.01480123 0.0612451" rpy="1.67549641 0.00015424 -0.75222007"/>
      <geometry>
        <mesh filename="./meshes/R_thumb_mpp_link.obj"/>
      </geometry>
    </visual>
    <visual name="R_thumb_cmp_link">
      <origin xyz="0.02931317 -0.00583109 0.05120011" rpy="-3.14158895 0.00000002 -0.75223629"/>
      <geometry>
        <mesh filename="./meshes/R_thumb_cmp_link.obj"/>
      </geometry>
    </visual>
    <visual name="R_index_ip_link">
      <origin xyz="0.03189266 -0.00849127 0.17975334" rpy="-1.69117805 -1.40292507 -1.45208361"/>
      <geometry>
        <mesh filename="./meshes/R_index_ip_link.obj"/>
      </geometry>
    </visual>
    <visual name="R_index_mpp_link">
      <origin xyz="0.03112682 -0.00149989 0.14159611" rpy="-1.68171769 -1.38852053 -1.46169058"/>
      <geometry>
        <mesh filename="./meshes/R_index_mpp_link.obj"/>
      </geometry>
    </visual>
    <visual name="R_middle_ip_link">
      <origin xyz="0.0107126 -0.00849108 0.17996472" rpy="-1.57072101 -1.40168899 -1.57081855"/>
      <geometry>
        <mesh filename="./meshes/R_middle_ip_link.obj"/>
      </geometry>
    </visual>
    <visual name="R_middle_mpp_link">
      <origin xyz="0.01146382 -0.00149996 0.14180004" rpy="-1.46545917 -1.38860185 -1.67783857"/>
      <geometry>
        <mesh filename="./meshes/R_middle_mpp_link.obj"/>
      </geometry>
    </visual>
    <visual name="R_ring_ip_link">
      <origin xyz="-0.01046625 -0.00849143 0.17975318" rpy="-1.45036277 -1.40292415 -1.68954551"/>
      <geometry>
        <mesh filename="./meshes/R_index_ip_link.obj"/>
      </geometry>
    </visual>
    <visual name="R_ring_mpp_link">
      <origin xyz="-0.00970018 -0.00150004 0.14159596" rpy="-1.45982714 -1.3885197 -1.67993446"/>
      <geometry>
        <mesh filename="./meshes/R_ring_mpp_link.obj"/>
      </geometry>
    </visual>
    <visual name="R_little_ip_link">
      <origin xyz="-0.03163693 -0.00849151 0.17911505" rpy="-1.33325164 -1.39939442 -1.80497966"/>
      <geometry>
        <mesh filename="./meshes/R_little_ip_link.obj"/>
      </geometry>
    </visual>
    <visual name="R_little_mpp_link">
      <origin xyz="-0.03010518 -0.00150011 0.14098089" rpy="-1.35145759 -1.38526931 -1.78648036"/>
      <geometry>
        <mesh filename="./meshes/R_little_mpp_link.obj"/>
      </geometry>
    </visual>
    <visual name="R_palm_link">
      <origin xyz="0.00035702 -0.013196 0.099778" rpy="-1.57079386 -1.57079263 -3.14159142"/>
      <geometry>
        <mesh filename="./meshes/R_palm_link.obj"/>
      </geometry>
    </visual>
    <visual name="R_hand_base_link">
      <geometry>
        <mesh filename="./meshes/R_hand_base_link.obj"/>
      </geometry>
    </visual>
    <collision name="R_thumb_ip_link">
      <origin xyz="0.0921168 -0.06604584 0.06123353" rpy="1.6755038 -0.01185903 -0.75348254"/>
      <geometry>
        <mesh filename="./meshes/R_thumb_ip_link.obj"/>
      </geometry>
    </collision>
    <collision name="R_thumb_mpp_link">
      <origin xyz="0.03735377 -0.01480123 0.0612451" rpy="1.67549641 0.00015424 -0.75222007"/>
      <geometry>
        <mesh filename="./meshes/R_thumb_mpp_link.obj"/>
      </geometry>
    </collision>
    <collision name="R_thumb_cmp_link">
      <origin xyz="0.02931317 -0.00583109 0.05120011" rpy="-3.14158895 0.00000002 -0.75223629"/>
      <geometry>
        <mesh filename="./meshes/R_thumb_cmp_link.obj"/>
      </geometry>
    </collision>
    <collision name="R_index_ip_link">
      <origin xyz="0.03189266 -0.00849127 0.17975334" rpy="-1.69117805 -1.40292507 -1.45208361"/>
      <geometry>
        <mesh filename="./meshes/R_index_ip_link.obj"/>
      </geometry>
    </collision>
    <collision name="R_index_mpp_link">
      <origin xyz="0.03112682 -0.00149989 0.14159611" rpy="-1.68171769 -1.38852053 -1.46169058"/>
      <geometry>
        <mesh filename="./meshes/R_index_mpp_link.obj"/>
      </geometry>
    </collision>
    <collision name="R_middle_ip_link">
      <origin xyz="0.0107126 -0.00849108 0.17996472" rpy="-1.57072101 -1.40168899 -1.57081855"/>
      <geometry>
        <mesh filename="./meshes/R_middle_ip_link.obj"/>
      </geometry>
    </collision>
    <collision name="R_middle_mpp_link">
      <origin xyz="0.01146382 -0.00149996 0.14180004" rpy="-1.46545917 -1.38860185 -1.67783857"/>
      <geometry>
        <mesh filename="./meshes/R_middle_mpp_link.obj"/>
      </geometry>
    </collision>
    <collision name="R_ring_ip_link">
      <origin xyz="-0.01046625 -0.00849143 0.17975318" rpy="-1.45036277 -1.40292415 -1.68954551"/>
      <geometry>
        <mesh filename="./meshes/R_index_ip_link.obj"/>
      </geometry>
    </collision>
    <collision name="R_ring_mpp_link">
      <origin xyz="-0.00970018 -0.00150004 0.14159596" rpy="-1.45982714 -1.3885197 -1.67993446"/>
      <geometry>
        <mesh filename="./meshes/R_ring_mpp_link.obj"/>
      </geometry>
    </collision>
    <collision name="R_little_ip_link">
      <origin xyz="-0.03163693 -0.00849151 0.17911505" rpy="-1.33325164 -1.39939442 -1.80497966"/>
      <geometry>
        <mesh filename="./meshes/R_little_ip_link.obj"/>
      </geometry>
    </collision>
    <collision name="R_little_mpp_link">
      <origin xyz="-0.03010518 -0.00150011 0.14098089" rpy="-1.35145759 -1.38526931 -1.78648036"/>
      <geometry>
        <mesh filename="./meshes/R_little_mpp_link.obj"/>
      </geometry>
    </collision>
    <collision name="R_palm_link">
      <origin xyz="0.00035702 -0.013196 0.099778" rpy="-1.57079386 -1.57079263 -3.14159142"/>
      <geometry>
        <mesh filename="./meshes/R_palm_link.obj"/>
      </geometry>
    </collision>
    <collision name="R_hand_base_link">
      <geometry>
        <mesh filename="./meshes/R_hand_base_link.obj"/>
      </geometry>
    </collision>
  </link>
  <link name="L_palm_link">
    <inertial>
      <origin xyz="-0.00938866 -0.00221701 -0.0117814" rpy="0 0 0"/>
      <mass value="0.38223591"/>
      <inertia ixx="0.00022773" ixy="-0.00000169" ixz="0.00000005" iyy="0.00035269" iyz="-0.00001316" izz="0.00050349"/>
    </inertial>
    <visual name="L_thumb_ip_link">
      <origin xyz="-0.0385448 0.09175944 0.05285018" rpy="3.03688526 -0.75223998 1.57080006"/>
      <geometry>
        <mesh filename="./meshes/L_thumb_ip_link.obj"/>
      </geometry>
    </visual>
    <visual name="L_thumb_mpp_link">
      <origin xyz="-0.03853303 0.0369966 0.00160537" rpy="3.03688526 -0.75223998 1.57080006"/>
      <geometry>
        <mesh filename="./meshes/L_thumb_mpp_link.obj"/>
      </geometry>
    </visual>
    <visual name="L_thumb_cmp_link">
      <origin xyz="-0.048578 0.028956 -0.0073648" rpy="-1.57080006 -0.75223998 1.57080006"/>
      <geometry>
        <mesh filename="./meshes/L_thumb_cmp_link.obj"/>
      </geometry>
    </visual>
    <visual name="L_index_ip_link">
      <origin xyz="0.07997423 0.03153496 -0.00470461" rpy="1.57080005 -0.16667876 0.02007104"/>
      <geometry>
        <mesh filename="./meshes/L_index_ip_link.obj"/>
      </geometry>
    </visual>
    <visual name="L_index_mpp_link">
      <origin xyz="0.041817 0.030769 -0.011696" rpy="1.57080006 -0.18118001 0.02007099"/>
      <geometry>
        <mesh filename="./meshes/L_index_mpp_link.obj"/>
      </geometry>
    </visual>
    <visual name="L_middle_ip_link">
      <origin xyz="0.08018692 0.010356 -0.00470461" rpy="1.57080007 -0.16912033 0.00000004"/>
      <geometry>
        <mesh filename="./meshes/L_middle_ip_link.obj"/>
      </geometry>
    </visual>
    <visual name="L_middle_mpp_link">
      <origin xyz="0.042022 0.010356 -0.011696" rpy="1.57080008 -0.18118 -0"/>
      <geometry>
        <mesh filename="./meshes/L_middle_mpp_link.obj"/>
      </geometry>
    </visual>
    <visual name="L_ring_ip_link">
      <origin xyz="0.07997423 -0.01082296 -0.00470461" rpy="1.57079995 -0.16667874 -0.02007095"/>
      <geometry>
        <mesh filename="./meshes/L_index_ip_link.obj"/>
      </geometry>
    </visual>
    <visual name="L_ring_mpp_link">
      <origin xyz="0.041817 -0.010057 -0.011696" rpy="1.57079996 -0.18117998 -0.020071"/>
      <geometry>
        <mesh filename="./meshes/L_middle_mpp_link.obj"/>
      </geometry>
    </visual>
    <visual name="L_little_ip_link">
      <origin xyz="0.07933717 -0.03199364 -0.00470461" rpy="1.57079991 -0.16667875 -0.04014294"/>
      <geometry>
        <mesh filename="./meshes/L_little_ip_link.obj"/>
      </geometry>
    </visual>
    <visual name="L_little_mpp_link">
      <origin xyz="0.041203 -0.030462 -0.011696" rpy="1.57079992 -0.18118 -0.04014299"/>
      <geometry>
        <mesh filename="./meshes/L_little_mpp_link.obj"/>
      </geometry>
    </visual>
    <visual name="L_palm_link">
      <geometry>
        <mesh filename="./meshes/L_palm_link.obj"/>
      </geometry>
    </visual>
    <collision name="L_thumb_ip_link">
      <origin xyz="-0.0385448 0.09175944 0.05285018" rpy="3.03688526 -0.75223998 1.57080006"/>
      <geometry>
        <mesh filename="./meshes/L_thumb_ip_link.obj"/>
      </geometry>
    </collision>
    <collision name="L_thumb_mpp_link">
      <origin xyz="-0.03853303 0.0369966 0.00160537" rpy="3.03688526 -0.75223998 1.57080006"/>
      <geometry>
        <mesh filename="./meshes/L_thumb_mpp_link.obj"/>
      </geometry>
    </collision>
    <collision name="L_thumb_cmp_link">
      <origin xyz="-0.048578 0.028956 -0.0073648" rpy="-1.57080006 -0.75223998 1.57080006"/>
      <geometry>
        <mesh filename="./meshes/L_thumb_cmp_link.obj"/>
      </geometry>
    </collision>
    <collision name="L_index_ip_link">
      <origin xyz="0.07997423 0.03153496 -0.00470461" rpy="1.57080005 -0.16667876 0.02007104"/>
      <geometry>
        <mesh filename="./meshes/L_index_ip_link.obj"/>
      </geometry>
    </collision>
    <collision name="L_index_mpp_link">
      <origin xyz="0.041817 0.030769 -0.011696" rpy="1.57080006 -0.18118001 0.02007099"/>
      <geometry>
        <mesh filename="./meshes/L_index_mpp_link.obj"/>
      </geometry>
    </collision>
    <collision name="L_middle_ip_link">
      <origin xyz="0.08018692 0.010356 -0.00470461" rpy="1.57080007 -0.16912033 0.00000004"/>
      <geometry>
        <mesh filename="./meshes/L_middle_ip_link.obj"/>
      </geometry>
    </collision>
    <collision name="L_middle_mpp_link">
      <origin xyz="0.042022 0.010356 -0.011696" rpy="1.57080008 -0.18118 -0"/>
      <geometry>
        <mesh filename="./meshes/L_middle_mpp_link.obj"/>
      </geometry>
    </collision>
    <collision name="L_ring_ip_link">
      <origin xyz="0.07997423 -0.01082296 -0.00470461" rpy="1.57079995 -0.16667874 -0.02007095"/>
      <geometry>
        <mesh filename="./meshes/L_index_ip_link.obj"/>
      </geometry>
    </collision>
    <collision name="L_ring_mpp_link">
      <origin xyz="0.041817 -0.010057 -0.011696" rpy="1.57079996 -0.18117998 -0.020071"/>
      <geometry>
        <mesh filename="./meshes/L_middle_mpp_link.obj"/>
      </geometry>
    </collision>
    <collision name="L_little_ip_link">
      <origin xyz="0.07933717 -0.03199364 -0.00470461" rpy="1.57079991 -0.16667875 -0.04014294"/>
      <geometry>
        <mesh filename="./meshes/L_little_ip_link.obj"/>
      </geometry>
    </collision>
    <collision name="L_little_mpp_link">
      <origin xyz="0.041203 -0.030462 -0.011696" rpy="1.57079992 -0.18118 -0.04014299"/>
      <geometry>
        <mesh filename="./meshes/L_little_mpp_link.obj"/>
      </geometry>
    </collision>
    <collision name="L_palm_link">
      <geometry>
        <mesh filename="./meshes/L_palm_link.obj"/>
      </geometry>
    </collision>
  </link>
  <link name="R_palm_link">
    <inertial>
      <origin xyz="-0.00938866 0.00221701 -0.0117814" rpy="0 0 0"/>
      <mass value="0.38223591"/>
      <inertia ixx="0.00022773" ixy="0.00000169" ixz="0.00000005" iyy="0.00035269" iyz="0.00001316" izz="0.00050349"/>
    </inertial>
    <visual name="R_thumb_ip_link">
      <origin xyz="-0.0385448 -0.09175944 0.05285018" rpy="0.09358288 -0.75342027 -1.55454003"/>
      <geometry>
        <mesh filename="./meshes/R_thumb_ip_link.obj"/>
      </geometry>
    </visual>
    <visual name="R_thumb_mpp_link">
      <origin xyz="-0.03853303 -0.0369966 0.00160537" rpy="0.10484442 -0.75222376 -1.57101127"/>
      <geometry>
        <mesh filename="./meshes/R_thumb_mpp_link.obj"/>
      </geometry>
    </visual>
    <visual name="R_thumb_cmp_link">
      <origin xyz="-0.048578 -0.028956 -0.0073648" rpy="1.57080006 -0.75223998 -1.57080006"/>
      <geometry>
        <mesh filename="./meshes/R_thumb_cmp_link.obj"/>
      </geometry>
    </visual>
    <visual name="R_index_ip_link">
      <origin xyz="0.07997523 -0.03153596 -0.00470461" rpy="1.57079995 -0.16667874 -0.02007095"/>
      <geometry>
        <mesh filename="./meshes/R_index_ip_link.obj"/>
      </geometry>
    </visual>
    <visual name="R_index_mpp_link">
      <origin xyz="0.041818 -0.03077 -0.011696" rpy="1.57079996 -0.18117998 -0.020071"/>
      <geometry>
        <mesh filename="./meshes/R_index_mpp_link.obj"/>
      </geometry>
    </visual>
    <visual name="R_middle_ip_link">
      <origin xyz="0.08018669 -0.0103559 -0.00470488" rpy="1.57084535 -0.16910734 0.00000073"/>
      <geometry>
        <mesh filename="./meshes/R_middle_ip_link.obj"/>
      </geometry>
    </visual>
    <visual name="R_middle_mpp_link">
      <origin xyz="0.042022 -0.011107 -0.011696" rpy="1.56730003 -0.18114001 0.019678"/>
      <geometry>
        <mesh filename="./meshes/R_middle_mpp_link.obj"/>
      </geometry>
    </visual>
    <visual name="R_ring_ip_link">
      <origin xyz="0.07997523 0.01082296 -0.00470461" rpy="1.57080005 -0.16667876 0.02007104"/>
      <geometry>
        <mesh filename="./meshes/R_index_ip_link.obj"/>
      </geometry>
    </visual>
    <visual name="R_ring_mpp_link">
      <origin xyz="0.041818 0.010057 -0.011696" rpy="1.57080006 -0.18118001 0.02007099"/>
      <geometry>
        <mesh filename="./meshes/R_ring_mpp_link.obj"/>
      </geometry>
    </visual>
    <visual name="R_little_ip_link">
      <origin xyz="0.07933717 0.03199364 -0.00470461" rpy="1.57079997 -0.16667875 0.04014306"/>
      <geometry>
        <mesh filename="./meshes/R_little_ip_link.obj"/>
      </geometry>
    </visual>
    <visual name="R_little_mpp_link">
      <origin xyz="0.041203 0.030462 -0.011696" rpy="1.57079998 -0.18118 0.04014301"/>
      <geometry>
        <mesh filename="./meshes/R_little_mpp_link.obj"/>
      </geometry>
    </visual>
    <visual name="R_palm_link">
      <geometry>
        <mesh filename="./meshes/R_palm_link.obj"/>
      </geometry>
    </visual>
    <collision name="R_thumb_ip_link">
      <origin xyz="-0.0385448 -0.09175944 0.05285018" rpy="0.09358288 -0.75342027 -1.55454003"/>
      <geometry>
        <mesh filename="./meshes/R_thumb_ip_link.obj"/>
      </geometry>
    </collision>
    <collision name="R_thumb_mpp_link">
      <origin xyz="-0.03853303 -0.0369966 0.00160537" rpy="0.10484442 -0.75222376 -1.57101127"/>
      <geometry>
        <mesh filename="./meshes/R_thumb_mpp_link.obj"/>
      </geometry>
    </collision>
    <collision name="R_thumb_cmp_link">
      <origin xyz="-0.048578 -0.028956 -0.0073648" rpy="1.57080006 -0.75223998 -1.57080006"/>
      <geometry>
        <mesh filename="./meshes/R_thumb_cmp_link.obj"/>
      </geometry>
    </collision>
    <collision name="R_index_ip_link">
      <origin xyz="0.07997523 -0.03153596 -0.00470461" rpy="1.57079995 -0.16667874 -0.02007095"/>
      <geometry>
        <mesh filename="./meshes/R_index_ip_link.obj"/>
      </geometry>
    </collision>
    <collision name="R_index_mpp_link">
      <origin xyz="0.041818 -0.03077 -0.011696" rpy="1.57079996 -0.18117998 -0.020071"/>
      <geometry>
        <mesh filename="./meshes/R_index_mpp_link.obj"/>
      </geometry>
    </collision>
    <collision name="R_middle_ip_link">
      <origin xyz="0.08018669 -0.0103559 -0.00470488" rpy="1.57084535 -0.16910734 0.00000073"/>
      <geometry>
        <mesh filename="./meshes/R_middle_ip_link.obj"/>
      </geometry>
    </collision>
    <collision name="R_middle_mpp_link">
      <origin xyz="0.042022 -0.011107 -0.011696" rpy="1.56730003 -0.18114001 0.019678"/>
      <geometry>
        <mesh filename="./meshes/R_middle_mpp_link.obj"/>
      </geometry>
    </collision>
    <collision name="R_ring_ip_link">
      <origin xyz="0.07997523 0.01082296 -0.00470461" rpy="1.57080005 -0.16667876 0.02007104"/>
      <geometry>
        <mesh filename="./meshes/R_index_ip_link.obj"/>
      </geometry>
    </collision>
    <collision name="R_ring_mpp_link">
      <origin xyz="0.041818 0.010057 -0.011696" rpy="1.57080006 -0.18118001 0.02007099"/>
      <geometry>
        <mesh filename="./meshes/R_ring_mpp_link.obj"/>
      </geometry>
    </collision>
    <collision name="R_little_ip_link">
      <origin xyz="0.07933717 0.03199364 -0.00470461" rpy="1.57079997 -0.16667875 0.04014306"/>
      <geometry>
        <mesh filename="./meshes/R_little_ip_link.obj"/>
      </geometry>
    </collision>
    <collision name="R_little_mpp_link">
      <origin xyz="0.041203 0.030462 -0.011696" rpy="1.57079998 -0.18118 0.04014301"/>
      <geometry>
        <mesh filename="./meshes/R_little_mpp_link.obj"/>
      </geometry>
    </collision>
    <collision name="R_palm_link">
      <geometry>
        <mesh filename="./meshes/R_palm_link.obj"/>
      </geometry>
    </collision>
  </link>
  <link name="L_thumb_cmp_link">
    <inertial>
      <origin xyz="0.00563085 -0.00075 -0.00435852" rpy="0 0 0"/>
      <mass value="0.01511033"/>
      <inertia ixx="0.00000093" ixy="0.00000007" ixz="0.0000003" iyy="0.00000105" iyz="-0.00000002" izz="0.00000107"/>
    </inertial>
    <visual name="L_thumb_ip_link">
      <origin xyz="0.08700001 -0.00105448 -0.01003344" rpy="-1.67549999 0.00000001 0.00000005"/>
      <geometry>
        <mesh filename="./meshes/L_thumb_ip_link.obj"/>
      </geometry>
    </visual>
    <visual name="L_thumb_mpp_link">
      <origin xyz="0.012 -0.0010557 -0.010045" rpy="-1.67549999 0.00000001 0.00000005"/>
      <geometry>
        <mesh filename="./meshes/L_thumb_mpp_link.obj"/>
      </geometry>
    </visual>
    <visual name="L_thumb_cmp_link">
      <origin xyz="0 0 -0" rpy="0 0.00000001 0.00000005"/>
      <geometry>
        <mesh filename="./meshes/L_thumb_cmp_link.obj"/>
      </geometry>
    </visual>
    <collision name="L_thumb_ip_link">
      <origin xyz="0.08700001 -0.00105448 -0.01003344" rpy="-1.67549999 0.00000001 0.00000005"/>
      <geometry>
        <mesh filename="./meshes/L_thumb_ip_link.obj"/>
      </geometry>
    </collision>
    <collision name="L_thumb_mpp_link">
      <origin xyz="0.012 -0.0010557 -0.010045" rpy="-1.67549999 0.00000001 0.00000005"/>
      <geometry>
        <mesh filename="./meshes/L_thumb_mpp_link.obj"/>
      </geometry>
    </collision>
    <collision name="L_thumb_cmp_link">
      <origin xyz="0 0 -0" rpy="0 0.00000001 0.00000005"/>
      <geometry>
        <mesh filename="./meshes/L_thumb_cmp_link.obj"/>
      </geometry>
    </collision>
  </link>
  <link name="L_index_mpp_link">
    <inertial>
      <origin xyz="0.01525314 -0.00181681 0.00015205" rpy="0 0 0"/>
      <mass value="0.01470075"/>
      <inertia ixx="0.00000087" ixy="0" ixz="0" iyy="0.00000357" iyz="0" izz="0.00000352"/>
    </inertial>
    <visual name="L_index_ip_link">
      <origin xyz="0.0388 -0 0" rpy="0.00000008 -0.00000001 -0.01450125"/>
      <geometry>
        <mesh filename="./meshes/L_index_ip_link.obj"/>
      </geometry>
    </visual>
    <visual name="L_index_mpp_link">
      <origin xyz="0 -0 -0" rpy="0.00000007 -0.00000001 -0"/>
      <geometry>
        <mesh filename="./meshes/L_index_mpp_link.obj"/>
      </geometry>
    </visual>
    <collision name="L_index_ip_link">
      <origin xyz="0.0388 -0 0" rpy="0.00000008 -0.00000001 -0.01450125"/>
      <geometry>
        <mesh filename="./meshes/L_index_ip_link.obj"/>
      </geometry>
    </collision>
    <collision name="L_index_mpp_link">
      <origin xyz="0 -0 -0" rpy="0.00000007 -0.00000001 -0"/>
      <geometry>
        <mesh filename="./meshes/L_index_mpp_link.obj"/>
      </geometry>
    </collision>
  </link>
  <link name="L_middle_mpp_link">
    <inertial>
      <origin xyz="0.01476009 -0.00171481 0.00012869" rpy="0 0 0"/>
      <mass value="0.01430214"/>
      <inertia ixx="0.00000086" ixy="-0.00000003" ixz="0" iyy="0.00000344" iyz="0" izz="0.00000339"/>
    </inertial>
    <visual name="L_middle_ip_link">
      <origin xyz="0.0388 -0 -0" rpy="0.00000003 0 -0.01205968"/>
      <geometry>
        <mesh filename="./meshes/L_middle_ip_link.obj"/>
      </geometry>
    </visual>
    <visual name="L_middle_mpp_link">
      <origin xyz="-0 -0 -0" rpy="0.00000003 0 0"/>
      <geometry>
        <mesh filename="./meshes/L_middle_mpp_link.obj"/>
      </geometry>
    </visual>
    <collision name="L_middle_ip_link">
      <origin xyz="0.0388 -0 -0" rpy="0.00000003 0 -0.01205968"/>
      <geometry>
        <mesh filename="./meshes/L_middle_ip_link.obj"/>
      </geometry>
    </collision>
    <collision name="L_middle_mpp_link">
      <origin xyz="-0 -0 -0" rpy="0.00000003 0 0"/>
      <geometry>
        <mesh filename="./meshes/L_middle_mpp_link.obj"/>
      </geometry>
    </collision>
  </link>
  <link name="L_ring_mpp_link">
    <inertial>
      <origin xyz="0.01475954 -0.00171495 0.00012869" rpy="0 0 0"/>
      <mass value="0.01430214"/>
      <inertia ixx="0.00000086" ixy="-0.00000003" ixz="0" iyy="0.00000344" iyz="0" izz="0.00000339"/>
    </inertial>
    <visual name="L_ring_ip_link">
      <origin xyz="0.0388 -0 -0" rpy="-0.0000001 0.00000001 -0.01450124"/>
      <geometry>
        <mesh filename="./meshes/L_index_ip_link.obj"/>
      </geometry>
    </visual>
    <visual name="L_ring_mpp_link">
      <origin xyz="0 -0 -0" rpy="-0.0000001 0.00000002 0.00000001"/>
      <geometry>
        <mesh filename="./meshes/L_middle_mpp_link.obj"/>
      </geometry>
    </visual>
    <collision name="L_ring_ip_link">
      <origin xyz="0.0388 -0 -0" rpy="-0.0000001 0.00000001 -0.01450124"/>
      <geometry>
        <mesh filename="./meshes/L_index_ip_link.obj"/>
      </geometry>
    </collision>
    <collision name="L_ring_mpp_link">
      <origin xyz="0 -0 -0" rpy="-0.0000001 0.00000002 0.00000001"/>
      <geometry>
        <mesh filename="./meshes/L_middle_mpp_link.obj"/>
      </geometry>
    </collision>
  </link>
  <link name="L_little_mpp_link">
    <inertial>
      <origin xyz="0.0147588 -0.00171514 0.00012869" rpy="0 0 0"/>
      <mass value="0.01430214"/>
      <inertia ixx="0.00000086" ixy="-0.00000003" ixz="0" iyy="0.00000344" iyz="0" izz="0.00000339"/>
    </inertial>
    <visual name="L_little_ip_link">
      <origin xyz="0.0388 -0 -0" rpy="-0.00000002 0 -0.01450124"/>
      <geometry>
        <mesh filename="./meshes/L_little_ip_link.obj"/>
      </geometry>
    </visual>
    <visual name="L_little_mpp_link">
      <origin xyz="0 -0 -0" rpy="-0.00000003 0.00000001 0"/>
      <geometry>
        <mesh filename="./meshes/L_little_mpp_link.obj"/>
      </geometry>
    </visual>
    <collision name="L_little_ip_link">
      <origin xyz="0.0388 -0 -0" rpy="-0.00000002 0 -0.01450124"/>
      <geometry>
        <mesh filename="./meshes/L_little_ip_link.obj"/>
      </geometry>
    </collision>
    <collision name="L_little_mpp_link">
      <origin xyz="0 -0 -0" rpy="-0.00000003 0.00000001 0"/>
      <geometry>
        <mesh filename="./meshes/L_little_mpp_link.obj"/>
      </geometry>
    </collision>
  </link>
  <link name="R_thumb_cmp_link">
    <inertial>
      <origin xyz="0.00563085 0.00075 -0.00435852" rpy="0 0 0"/>
      <mass value="0.01511033"/>
      <inertia ixx="0.00000093" ixy="-0.00000007" ixz="0.0000003" iyy="0.00000105" iyz="0.00000002" izz="0.00000107"/>
    </inertial>
    <visual name="R_thumb_ip_link">
      <origin xyz="0.087 0.00105448 -0.01003344" rpy="-1.46609256 0.01185907 0.00124616"/>
      <geometry>
        <mesh filename="./meshes/R_thumb_ip_link.obj"/>
      </geometry>
    </visual>
    <visual name="R_thumb_mpp_link">
      <origin xyz="0.012 0.0010557 -0.010045" rpy="-1.46609995 -0.00015421 -0.00001626"/>
      <geometry>
        <mesh filename="./meshes/R_thumb_mpp_link.obj"/>
      </geometry>
    </visual>
    <visual name="R_thumb_cmp_link">
      <origin xyz="0 0 -0" rpy="-0 0.00000001 -0.00000005"/>
      <geometry>
        <mesh filename="./meshes/R_thumb_cmp_link.obj"/>
      </geometry>
    </visual>
    <collision name="R_thumb_ip_link">
      <origin xyz="0.087 0.00105448 -0.01003344" rpy="-1.46609256 0.01185907 0.00124616"/>
      <geometry>
        <mesh filename="./meshes/R_thumb_ip_link.obj"/>
      </geometry>
    </collision>
    <collision name="R_thumb_mpp_link">
      <origin xyz="0.012 0.0010557 -0.010045" rpy="-1.46609995 -0.00015421 -0.00001626"/>
      <geometry>
        <mesh filename="./meshes/R_thumb_mpp_link.obj"/>
      </geometry>
    </collision>
    <collision name="R_thumb_cmp_link">
      <origin xyz="0 0 -0" rpy="-0 0.00000001 -0.00000005"/>
      <geometry>
        <mesh filename="./meshes/R_thumb_cmp_link.obj"/>
      </geometry>
    </collision>
  </link>
  <link name="R_index_mpp_link">
    <inertial>
      <origin xyz="0.01525314 -0.00181681 -0.00015205" rpy="0 0 0"/>
      <mass value="0.01470075"/>
      <inertia ixx="0.00000087" ixy="0" ixz="0" iyy="0.00000357" iyz="0" izz="0.00000352"/>
    </inertial>
    <visual name="R_index_ip_link">
      <origin xyz="0.0388 -0 -0" rpy="-0.0000001 0.00000001 -0.01450124"/>
      <geometry>
        <mesh filename="./meshes/R_index_ip_link.obj"/>
      </geometry>
    </visual>
    <visual name="R_index_mpp_link">
      <origin xyz="-0 -0 0" rpy="-0.00000011 0.00000002 0.00000001"/>
      <geometry>
        <mesh filename="./meshes/R_index_mpp_link.obj"/>
      </geometry>
    </visual>
    <collision name="R_index_ip_link">
      <origin xyz="0.0388 -0 -0" rpy="-0.0000001 0.00000001 -0.01450124"/>
      <geometry>
        <mesh filename="./meshes/R_index_ip_link.obj"/>
      </geometry>
    </collision>
    <collision name="R_index_mpp_link">
      <origin xyz="-0 -0 0" rpy="-0.00000011 0.00000002 0.00000001"/>
      <geometry>
        <mesh filename="./meshes/R_index_mpp_link.obj"/>
      </geometry>
    </collision>
  </link>
  <link name="R_middle_mpp_link">
    <inertial>
      <origin xyz="0.01476009 -0.00171481 -0.00012869" rpy="0 0 0"/>
      <mass value="0.01430214"/>
      <inertia ixx="0.00000086" ixy="-0.00000003" ixz="0" iyy="0.00000344" iyz="0" izz="0.00000339"/>
    </inertial>
    <visual name="R_middle_ip_link">
      <origin xyz="0.038807 -0 0" rpy="0.00023365 -0.01935449 -0.0120683"/>
      <geometry>
        <mesh filename="./meshes/R_middle_ip_link.obj"/>
      </geometry>
    </visual>
    <visual name="R_middle_mpp_link">
      <origin xyz="-0 -0 0" rpy="0.00000007 -0.00000001 0"/>
      <geometry>
        <mesh filename="./meshes/R_middle_mpp_link.obj"/>
      </geometry>
    </visual>
    <collision name="R_middle_ip_link">
      <origin xyz="0.038807 -0 0" rpy="0.00023365 -0.01935449 -0.0120683"/>
      <geometry>
        <mesh filename="./meshes/R_middle_ip_link.obj"/>
      </geometry>
    </collision>
    <collision name="R_middle_mpp_link">
      <origin xyz="-0 -0 0" rpy="0.00000007 -0.00000001 0"/>
      <geometry>
        <mesh filename="./meshes/R_middle_mpp_link.obj"/>
      </geometry>
    </collision>
  </link>
  <link name="R_ring_mpp_link">
    <inertial>
      <origin xyz="0.01475954 -0.00171495 -0.00012869" rpy="0 0 0"/>
      <mass value="0.01430214"/>
      <inertia ixx="0.00000086" ixy="-0.00000003" ixz="0" iyy="0.00000344" iyz="0" izz="0.00000339"/>
    </inertial>
    <visual name="R_ring_ip_link">
      <origin xyz="0.0388 -0 0" rpy="0.00000008 -0.00000001 -0.01450125"/>
      <geometry>
        <mesh filename="./meshes/R_index_ip_link.obj"/>
      </geometry>
    </visual>
    <visual name="R_ring_mpp_link">
      <origin xyz="-0 -0 0" rpy="0.00000008 -0.00000001 -0"/>
      <geometry>
        <mesh filename="./meshes/R_ring_mpp_link.obj"/>
      </geometry>
    </visual>
    <collision name="R_ring_ip_link">
      <origin xyz="0.0388 -0 0" rpy="0.00000008 -0.00000001 -0.01450125"/>
      <geometry>
        <mesh filename="./meshes/R_index_ip_link.obj"/>
      </geometry>
    </collision>
    <collision name="R_ring_mpp_link">
      <origin xyz="-0 -0 0" rpy="0.00000008 -0.00000001 -0"/>
      <geometry>
        <mesh filename="./meshes/R_ring_mpp_link.obj"/>
      </geometry>
    </collision>
  </link>
  <link name="R_little_mpp_link">
    <inertial>
      <origin xyz="0.0147588 -0.00171514 -0.00012869" rpy="0 0 0"/>
      <mass value="0.01430214"/>
      <inertia ixx="0.00000086" ixy="-0.00000003" ixz="0" iyy="0.00000344" iyz="0" izz="0.00000339"/>
    </inertial>
    <visual name="R_little_ip_link">
      <origin xyz="0.0388 -0 0" rpy="-0.00000009 0.00000001 -0.01450125"/>
      <geometry>
        <mesh filename="./meshes/R_little_ip_link.obj"/>
      </geometry>
    </visual>
    <visual name="R_little_mpp_link">
      <origin xyz="0 -0 0" rpy="-0.00000009 0.00000001 -0"/>
      <geometry>
        <mesh filename="./meshes/R_little_mpp_link.obj"/>
      </geometry>
    </visual>
    <collision name="R_little_ip_link">
      <origin xyz="0.0388 -0 0" rpy="-0.00000009 0.00000001 -0.01450125"/>
      <geometry>
        <mesh filename="./meshes/R_little_ip_link.obj"/>
      </geometry>
    </collision>
    <collision name="R_little_mpp_link">
      <origin xyz="0 -0 0" rpy="-0.00000009 0.00000001 -0"/>
      <geometry>
        <mesh filename="./meshes/R_little_mpp_link.obj"/>
      </geometry>
    </collision>
  </link>
  <link name="L_thumb_mpp_link">
    <inertial>
      <origin xyz="0.03618423 -0.00195018 -0.00007704" rpy="0 0 0"/>
      <mass value="0.06741198"/>
      <inertia ixx="0.00000637" ixy="-0.00000267" ixz="0.00000003" iyy="0.00003296" iyz="0" izz="0.00003268"/>
    </inertial>
    <visual name="L_thumb_ip_link">
      <origin xyz="0.075 -0.00001163 0" rpy="-0.00000003 0 0"/>
      <geometry>
        <mesh filename="./meshes/L_thumb_ip_link.obj"/>
      </geometry>
    </visual>
    <visual name="L_thumb_mpp_link">
      <origin xyz="-0 -0 0" rpy="-0.00000003 0 0"/>
      <geometry>
        <mesh filename="./meshes/L_thumb_mpp_link.obj"/>
      </geometry>
    </visual>
    <collision name="L_thumb_ip_link">
      <origin xyz="0.075 -0.00001163 0" rpy="-0.00000003 0 0"/>
      <geometry>
        <mesh filename="./meshes/L_thumb_ip_link.obj"/>
      </geometry>
    </collision>
    <collision name="L_thumb_mpp_link">
      <origin xyz="-0 -0 0" rpy="-0.00000003 0 0"/>
      <geometry>
        <mesh filename="./meshes/L_thumb_mpp_link.obj"/>
      </geometry>
    </collision>
  </link>
  <link name="L_index_ip_link">
    <inertial>
      <origin xyz="0.01680857 -0.00117535 0" rpy="0 0 0"/>
      <mass value="0.01334933"/>
      <inertia ixx="0.00000042" ixy="-0.00000029" ixz="0" iyy="0.00000262" iyz="0" izz="0.00000261"/>
    </inertial>
    <visual name="L_index_ip_link">
      <geometry>
        <mesh filename="./meshes/L_index_ip_link.obj"/>
      </geometry>
    </visual>
    <collision name="L_index_ip_link">
      <geometry>
        <mesh filename="./meshes/L_index_ip_link.obj"/>
      </geometry>
    </collision>
  </link>
  <link name="L_middle_ip_link">
    <inertial>
      <origin xyz="0.01771317 -0.00109666 0.0000256" rpy="0 0 0"/>
      <mass value="0.0148881"/>
      <inertia ixx="0.00000047" ixy="-0.00000038" ixz="0" iyy="0.00000344" iyz="0" izz="0.00000344"/>
    </inertial>
    <visual name="L_middle_ip_link">
      <geometry>
        <mesh filename="./meshes/L_middle_ip_link.obj"/>
      </geometry>
    </visual>
    <collision name="L_middle_ip_link">
      <geometry>
        <mesh filename="./meshes/L_middle_ip_link.obj"/>
      </geometry>
    </collision>
  </link>
  <link name="L_ring_ip_link">
    <inertial>
      <origin xyz="0.01615432 -0.00130235 0.00002763" rpy="0 0 0"/>
      <mass value="0.01374794"/>
      <inertia ixx="0.00000043" ixy="-0.00000033" ixz="0" iyy="0.00000282" iyz="0" izz="0.00000281"/>
    </inertial>
    <visual name="L_ring_ip_link">
      <geometry>
        <mesh filename="./meshes/L_index_ip_link.obj"/>
      </geometry>
    </visual>
    <collision name="L_ring_ip_link">
      <geometry>
        <mesh filename="./meshes/L_index_ip_link.obj"/>
      </geometry>
    </collision>
  </link>
  <link name="L_little_ip_link">
    <inertial>
      <origin xyz="0.01303327 -0.00143438 0.0000295" rpy="0 0 0"/>
      <mass value="0.01179268"/>
      <inertia ixx="0.00000034" ixy="-0.00000023" ixz="0" iyy="0.00000179" iyz="0" izz="0.00000178"/>
    </inertial>
    <visual name="L_little_ip_link">
      <geometry>
        <mesh filename="./meshes/L_little_ip_link.obj"/>
      </geometry>
    </visual>
    <collision name="L_little_ip_link">
      <geometry>
        <mesh filename="./meshes/L_little_ip_link.obj"/>
      </geometry>
    </collision>
  </link>
  <link name="R_thumb_mpp_link">
    <inertial>
      <origin xyz="0.03618423 -0.00195018 0.00007704" rpy="0 0 0"/>
      <mass value="0.06741198"/>
      <inertia ixx="0.00000637" ixy="-0.00000267" ixz="-0.00000003" iyy="0.00003296" iyz="0" izz="0.00003268"/>
    </inertial>
    <visual name="R_thumb_ip_link">
      <origin xyz="0.075 -0 0" rpy="-0.00000009 0 0.01207943"/>
      <geometry>
        <mesh filename="./meshes/R_thumb_ip_link.obj"/>
      </geometry>
    </visual>
    <visual name="R_thumb_mpp_link">
      <origin xyz="-0 -0 0" rpy="-0.00000009 0 0"/>
      <geometry>
        <mesh filename="./meshes/R_thumb_mpp_link.obj"/>
      </geometry>
    </visual>
    <collision name="R_thumb_ip_link">
      <origin xyz="0.075 -0 0" rpy="-0.00000009 0 0.01207943"/>
      <geometry>
        <mesh filename="./meshes/R_thumb_ip_link.obj"/>
      </geometry>
    </collision>
    <collision name="R_thumb_mpp_link">
      <origin xyz="-0 -0 0" rpy="-0.00000009 0 0"/>
      <geometry>
        <mesh filename="./meshes/R_thumb_mpp_link.obj"/>
      </geometry>
    </collision>
  </link>
  <link name="R_index_ip_link">
    <inertial>
      <origin xyz="0.01680857 -0.00117535 0" rpy="0 0 0"/>
      <mass value="0.01334933"/>
      <inertia ixx="0.00000042" ixy="-0.00000029" ixz="0" iyy="0.00000262" iyz="0" izz="0.00000261"/>
    </inertial>
    <visual name="R_index_ip_link">
      <geometry>
        <mesh filename="./meshes/R_index_ip_link.obj"/>
      </geometry>
    </visual>
    <collision name="R_index_ip_link">
      <geometry>
        <mesh filename="./meshes/R_index_ip_link.obj"/>
      </geometry>
    </collision>
  </link>
  <link name="R_middle_ip_link">
    <inertial>
      <origin xyz="0.01771317 -0.00109666 -0.0000256" rpy="0 0 0"/>
      <mass value="0.0148881"/>
      <inertia ixx="0.00000047" ixy="-0.00000038" ixz="0" iyy="0.00000344" iyz="0" izz="0.00000344"/>
    </inertial>
    <visual name="R_middle_ip_link">
      <geometry>
        <mesh filename="./meshes/R_middle_ip_link.obj"/>
      </geometry>
    </visual>
    <collision name="R_middle_ip_link">
      <geometry>
        <mesh filename="./meshes/R_middle_ip_link.obj"/>
      </geometry>
    </collision>
  </link>
  <link name="R_ring_ip_link">
    <inertial>
      <origin xyz="0.01615432 -0.00130235 -0.00002763" rpy="0 0 0"/>
      <mass value="0.01374794"/>
      <inertia ixx="0.00000043" ixy="-0.00000033" ixz="0" iyy="0.00000282" iyz="0" izz="0.00000281"/>
    </inertial>
    <visual name="R_ring_ip_link">
      <geometry>
        <mesh filename="./meshes/R_index_ip_link.obj"/>
      </geometry>
    </visual>
    <collision name="R_ring_ip_link">
      <geometry>
        <mesh filename="./meshes/R_index_ip_link.obj"/>
      </geometry>
    </collision>
  </link>
  <link name="R_little_ip_link">
    <inertial>
      <origin xyz="0.01303327 -0.00143438 -0.0000295" rpy="0 0 0"/>
      <mass value="0.01179268"/>
      <inertia ixx="0.00000034" ixy="-0.00000023" ixz="0" iyy="0.00000179" iyz="0" izz="0.00000178"/>
    </inertial>
    <visual name="R_little_ip_link">
      <geometry>
        <mesh filename="./meshes/R_little_ip_link.obj"/>
      </geometry>
    </visual>
    <collision name="R_little_ip_link">
      <geometry>
        <mesh filename="./meshes/R_little_ip_link.obj"/>
      </geometry>
    </collision>
  </link>
  <link name="L_thumb_ip_link">
    <inertial>
      <origin xyz="0.01353705 0.00416931 0.00000614" rpy="0 0 0"/>
      <mass value="0.01731117"/>
      <inertia ixx="0.00000104" ixy="-0.00000015" ixz="0" iyy="0.00000185" iyz="0" izz="0.00000176"/>
    </inertial>
    <visual name="L_thumb_ip_link">
      <geometry>
        <mesh filename="./meshes/L_thumb_ip_link.obj"/>
      </geometry>
    </visual>
    <collision name="L_thumb_ip_link">
      <geometry>
        <mesh filename="./meshes/L_thumb_ip_link.obj"/>
      </geometry>
    </collision>
  </link>
  <link name="R_thumb_ip_link">
    <inertial>
      <origin xyz="0.01353705 0.00416931 -0.00000614" rpy="0 0 0"/>
      <mass value="0.01731117"/>
      <inertia ixx="0.00000104" ixy="-0.00000015" ixz="0" iyy="0.00000185" iyz="0" izz="0.00000176"/>
    </inertial>
    <visual name="R_thumb_ip_link">
      <geometry>
        <mesh filename="./meshes/R_thumb_ip_link.obj"/>
      </geometry>
    </visual>
    <collision name="R_thumb_ip_link">
      <geometry>
        <mesh filename="./meshes/R_thumb_ip_link.obj"/>
      </geometry>
    </collision>
  </link>
  <joint name="floating_base" type="floating">
    <parent link="world"/>
    <child link="base_link"/>
  </joint>
  <joint name="L_hip_roll_joint" type="revolute">
    <origin xyz="0 0.105 0" rpy="3.14159265 1.57079263 3.14159265"/>
    <parent link="base_link"/>
    <child link="L_hip_roll_link"/>
    <axis xyz="0 0 1"/>
    <limit lower="-0.43629999" upper="0.78529996" velocity="8.37758041"/>
    <dynamics friction="0"/>
    <!-- isaac:source_drive {"armature": 0.0, "drive": {"damping": 3.0, "max_force": 225.0, "stiffness": 300.0, "target_position": 0.0}, "instance": "angular", "source": "physx"} -->
  </joint>
  <joint name="R_hip_roll_joint" type="revolute">
    <origin xyz="0 -0.105 0" rpy="3.14159265 1.57079263 3.14159265"/>
    <parent link="base_link"/>
    <child link="R_hip_roll_link"/>
    <axis xyz="0 0 1"/>
    <limit lower="-0.78529996" upper="0.43629999" velocity="8.37758041"/>
    <dynamics friction="0"/>
    <!-- isaac:source_drive {"armature": 0.0, "drive": {"damping": 3.0, "max_force": 225.0, "stiffness": 300.0, "target_position": 0.0}, "instance": "angular", "source": "physx"} -->
  </joint>
  <joint name="waist_yaw_joint" type="revolute">
    <origin xyz="0 0 0.14300001" rpy="-3.14158541 0 0"/>
    <parent link="base_link"/>
    <child link="waist_yaw_link"/>
    <axis xyz="0 0 1"/>
    <limit lower="-2.82739983" upper="2.82739983" velocity="3.87463067"/>
    <dynamics friction="0"/>
    <!-- isaac:source_drive {"armature": 0.0, "drive": {"damping": 3.0, "max_force": 85.0, "stiffness": 300.0, "target_position": 0.0}, "instance": "angular", "source": "physx"} -->
  </joint>
  <joint name="L_hip_yaw_joint" type="revolute">
    <origin xyz="0 0 0" rpy="-1.53744238 -1.5707927 -1.60414303"/>
    <parent link="L_hip_roll_link"/>
    <child link="L_hip_yaw_link"/>
    <axis xyz="0 0 1"/>
    <limit lower="-0.78529996" upper="1.04709988" velocity="8.37758041"/>
    <dynamics friction="0"/>
    <!-- isaac:source_drive {"armature": 0.0, "drive": {"damping": 3.0, "max_force": 65.0, "stiffness": 300.0, "target_position": 0.0}, "instance": "angular", "source": "physx"} -->
  </joint>
  <joint name="R_hip_yaw_joint" type="revolute">
    <origin xyz="0 0 0" rpy="-1.53744238 -1.5707927 -1.60414303"/>
    <parent link="R_hip_roll_link"/>
    <child link="R_hip_yaw_link"/>
    <axis xyz="0 0 1"/>
    <limit lower="-1.04709988" upper="0.78529996" velocity="8.37758041"/>
    <dynamics friction="0"/>
    <!-- isaac:source_drive {"armature": 0.0, "drive": {"damping": 3.0, "max_force": 65.0, "stiffness": 300.0, "target_position": 0.0}, "instance": "angular", "source": "physx"} -->
  </joint>
  <joint name="waist_pitch_joint" type="revolute">
    <origin xyz="0 0 0" rpy="-1.57080002 0 0"/>
    <parent link="waist_yaw_link"/>
    <child link="waist_pitch_link"/>
    <axis xyz="0 0 1"/>
    <limit lower="-1.57069992" upper="0.61079999" velocity="2.09439976"/>
    <dynamics friction="0"/>
    <!-- isaac:source_drive {"armature": 0.0, "drive": {"damping": 3.0, "max_force": 265.0, "stiffness": 300.0, "target_position": 0.0}, "instance": "angular", "source": "physx"} -->
  </joint>
  <joint name="L_hip_pitch_joint" type="revolute">
    <origin xyz="0.00000001 0 0.12199999" rpy="-1.57080002 -0.00000006 0"/>
    <parent link="L_hip_yaw_link"/>
    <child link="L_hip_pitch_link"/>
    <axis xyz="0 0 1"/>
    <limit lower="-0.349" upper="1.91979999" velocity="8.37758041"/>
    <dynamics friction="0"/>
    <!-- isaac:source_drive {"armature": 0.0, "drive": {"damping": 3.0, "max_force": 225.0, "stiffness": 300.0, "target_position": 0.0}, "instance": "angular", "source": "physx"} -->
  </joint>
  <joint name="R_hip_pitch_joint" type="revolute">
    <origin xyz="0.00000001 0 0.12199999" rpy="-1.57080002 -0.00000006 0"/>
    <parent link="R_hip_yaw_link"/>
    <child link="R_hip_pitch_link"/>
    <axis xyz="0 0 1"/>
    <limit lower="-0.349" upper="1.91979999" velocity="8.37758041"/>
    <dynamics friction="0"/>
    <!-- isaac:source_drive {"armature": 0.0, "drive": {"damping": 3.0, "max_force": 225.0, "stiffness": 300.0, "target_position": 0.0}, "instance": "angular", "source": "physx"} -->
  </joint>
  <joint name="torso_waist_joint" type="fixed">
    <origin xyz="-0.0046 0.34863999 0.00000001" rpy="-1.57079999 0 0"/>
    <parent link="waist_pitch_link"/>
    <child link="torso_link"/>
  </joint>
  <joint name="L_knee_pitch_joint" type="revolute">
    <origin xyz="0 -0.36000001 0.00000005" rpy="-0.00000015 0 0"/>
    <parent link="L_hip_pitch_link"/>
    <child link="L_knee_pitch_link"/>
    <axis xyz="0 0 1"/>
    <limit lower="-2.2688998" upper="0.0872" velocity="8.37758041"/>
    <dynamics friction="0"/>
    <!-- isaac:source_drive {"armature": 0.0, "drive": {"damping": 3.0, "max_force": 225.0, "stiffness": 300.0, "target_position": 0.0}, "instance": "angular", "source": "physx"} -->
  </joint>
  <joint name="R_knee_pitch_joint" type="revolute">
    <origin xyz="0 -0.36000001 0.00000005" rpy="-0.00000015 0 0"/>
    <parent link="R_hip_pitch_link"/>
    <child link="R_knee_pitch_link"/>
    <axis xyz="0 0 1"/>
    <limit lower="-2.2688998" upper="0.0872" velocity="8.37758041"/>
    <dynamics friction="0"/>
    <!-- isaac:source_drive {"armature": 0.0, "drive": {"damping": 3.0, "max_force": 225.0, "stiffness": 300.0, "target_position": 0.0}, "instance": "angular", "source": "physx"} -->
  </joint>
  <joint name="L_shoulder_pitch_joint" type="revolute">
    <origin xyz="-0 0.15387 0.00000002" rpy="3.14159265 -1.39626244 -1.57079268"/>
    <parent link="torso_link"/>
    <child link="L_shoulder_pitch_link"/>
    <axis xyz="0 0 1"/>
    <limit lower="-2.86229976" upper="2.86229976" velocity="3.14159984"/>
    <dynamics friction="0"/>
    <!-- isaac:source_drive {"armature": 0.0, "drive": {"damping": 3.0, "max_force": 80.0, "stiffness": 300.0, "target_position": 0.0}, "instance": "angular", "source": "physx"} -->
  </joint>
  <joint name="R_shoulder_pitch_joint" type="revolute">
    <origin xyz="-0 -0.15387 -0.00000002" rpy="-3.14158539 -1.39627028 1.5708"/>
    <parent link="torso_link"/>
    <child link="R_shoulder_pitch_link"/>
    <axis xyz="0 0 1"/>
    <limit lower="-2.86229976" upper="2.86229976" velocity="3.14159984"/>
    <dynamics friction="0"/>
    <!-- isaac:source_drive {"armature": 0.0, "drive": {"damping": 3.0, "max_force": 80.0, "stiffness": 300.0, "target_position": 0.0}, "instance": "angular", "source": "physx"} -->
  </joint>
  <joint name="head_yaw_joint" type="revolute">
    <origin xyz="-0 -0.00000002 0.13546" rpy="0.00000012 0 0"/>
    <parent link="torso_link"/>
    <child link="head_yaw_link"/>
    <axis xyz="0 0 1"/>
    <limit lower="-1.65799994" upper="1.65799994" velocity="5.23598722"/>
    <dynamics friction="0"/>
    <!-- isaac:source_drive {"armature": 0.0, "drive": {"damping": 3.0, "max_force": 4.5, "stiffness": 300.0, "target_position": 0.0}, "instance": "angular", "source": "physx"} -->
  </joint>
  <joint name="L_ankle_pitch_joint" type="revolute">
    <origin xyz="0 -0.3700001 0" rpy="0 0 0"/>
    <parent link="L_knee_pitch_link"/>
    <child link="L_ankle_pitch_link"/>
    <axis xyz="0 0 1"/>
    <limit lower="-0.52350001" upper="1.04709988" velocity="8.37758041"/>
    <dynamics friction="0"/>
    <!-- isaac:source_drive {"armature": 0.0, "drive": {"damping": 3.0, "max_force": 65.0, "stiffness": 300.0, "target_position": 0.0}, "instance": "angular", "source": "physx"} -->
  </joint>
  <joint name="R_ankle_pitch_joint" type="revolute">
    <origin xyz="0 -0.3700001 0" rpy="0 0 0"/>
    <parent link="R_knee_pitch_link"/>
    <child link="R_ankle_pitch_link"/>
    <axis xyz="0 0 1"/>
    <limit lower="-0.52350001" upper="1.04709988" velocity="8.37758041"/>
    <dynamics friction="0"/>
    <!-- isaac:source_drive {"armature": 0.0, "drive": {"damping": 3.0, "max_force": 65.0, "stiffness": 300.0, "target_position": 0.0}, "instance": "angular", "source": "physx"} -->
  </joint>
  <joint name="L_shoulder_roll_joint" type="revolute">
    <origin xyz="-0.00000001 -0 -0.05999999" rpy="-1.57080007 0.00000009 -0.00000003"/>
    <parent link="L_shoulder_pitch_link"/>
    <child link="L_shoulder_roll_link"/>
    <axis xyz="0 0 1"/>
    <limit lower="-1.88499993" upper="0.12219999" velocity="3.14159984"/>
    <dynamics friction="0"/>
    <!-- isaac:source_drive {"armature": 0.0, "drive": {"damping": 3.0, "max_force": 80.0, "stiffness": 300.0, "target_position": 0.0}, "instance": "angular", "source": "physx"} -->
  </joint>
  <joint name="R_shoulder_roll_joint" type="revolute">
    <origin xyz="0.00000001 -0 -0.06" rpy="-1.57080006 -0.00000008 -0.00000005"/>
    <parent link="R_shoulder_pitch_link"/>
    <child link="R_shoulder_roll_link"/>
    <axis xyz="0 0 1"/>
    <limit lower="-1.88499993" upper="0.12219999" velocity="3.14159984"/>
    <dynamics friction="0"/>
    <!-- isaac:source_drive {"armature": 0.0, "drive": {"damping": 3.0, "max_force": 80.0, "stiffness": 300.0, "target_position": 0.0}, "instance": "angular", "source": "physx"} -->
  </joint>
  <joint name="head_pitch_joint" type="revolute">
    <origin xyz="0 0 0.02499999" rpy="1.57080002 0 0"/>
    <parent link="head_yaw_link"/>
    <child link="head_pitch_link"/>
    <axis xyz="0 0 1"/>
    <limit lower="-0.78539996" upper="0.52359994" velocity="5.23598722"/>
    <dynamics friction="0"/>
    <!-- isaac:source_drive {"armature": 0.0, "drive": {"damping": 3.0, "max_force": 4.5, "stiffness": 300.0, "target_position": 0.0}, "instance": "angular", "source": "physx"} -->
  </joint>
  <joint name="L_ankle_roll_joint" type="revolute">
    <origin xyz="0 -0.00000012 0" rpy="1.57079999 0.00000003 1.57079999"/>
    <parent link="L_ankle_pitch_link"/>
    <child link="L_ankle_roll_link"/>
    <axis xyz="0 0 1"/>
    <limit lower="-0.52350001" upper="0.52350001" velocity="8.37758041"/>
    <dynamics friction="0"/>
    <!-- isaac:source_drive {"armature": 0.0, "drive": {"damping": 3.0, "max_force": 65.0, "stiffness": 300.0, "target_position": 0.0}, "instance": "angular", "source": "physx"} -->
  </joint>
  <joint name="R_ankle_roll_joint" type="revolute">
    <origin xyz="0 -0.00000012 0" rpy="1.57079999 0.00000003 1.57079999"/>
    <parent link="R_ankle_pitch_link"/>
    <child link="R_ankle_roll_link"/>
    <axis xyz="0 0 1"/>
    <limit lower="-0.52350001" upper="0.52350001" velocity="8.37758041"/>
    <dynamics friction="0"/>
    <!-- isaac:source_drive {"armature": 0.0, "drive": {"damping": 3.0, "max_force": 65.0, "stiffness": 300.0, "target_position": 0.0}, "instance": "angular", "source": "physx"} -->
  </joint>
  <joint name="L_shoulder_yaw_joint" type="revolute">
    <origin xyz="-0.08300001 -0 0.00000001" rpy="-1.57079989 -0.00000012 1.57079996"/>
    <parent link="L_shoulder_roll_link"/>
    <child link="L_shoulder_yaw_link"/>
    <axis xyz="0 0 1"/>
    <limit lower="-2.93219975" upper="2.93219975" velocity="3.14159984"/>
    <dynamics friction="0"/>
    <!-- isaac:source_drive {"armature": 0.0, "drive": {"damping": 3.0, "max_force": 45.0, "stiffness": 300.0, "target_position": 0.0}, "instance": "angular", "source": "physx"} -->
  </joint>
  <joint name="R_shoulder_yaw_joint" type="revolute">
    <origin xyz="-0.08299999 -0 0" rpy="-1.57079989 -0.02002311 1.57079993"/>
    <parent link="R_shoulder_roll_link"/>
    <child link="R_shoulder_yaw_link"/>
    <axis xyz="0 0 1"/>
    <limit lower="-2.93219975" upper="2.93219975" velocity="3.14159984"/>
    <dynamics friction="0"/>
    <!-- isaac:source_drive {"armature": 0.0, "drive": {"damping": 3.0, "max_force": 45.0, "stiffness": 300.0, "target_position": 0.0}, "instance": "angular", "source": "physx"} -->
  </joint>
  <joint name="L_elbow_roll_joint" type="revolute">
    <origin xyz="-0.019993 0.00000001 0.21300001" rpy="-1.57080008 0.00000004 -0.00000004"/>
    <parent link="L_shoulder_yaw_link"/>
    <child link="L_elbow_roll_link"/>
    <axis xyz="0 0 1"/>
    <limit lower="-2.65289993" upper="0.0349" velocity="3.14159984"/>
    <dynamics friction="0"/>
    <!-- isaac:source_drive {"armature": 0.0, "drive": {"damping": 3.0, "max_force": 45.0, "stiffness": 300.0, "target_position": 0.0}, "instance": "angular", "source": "physx"} -->
  </joint>
  <joint name="R_elbow_roll_joint" type="revolute">
    <origin xyz="-0.01998901 -0.00040027 0.21299999" rpy="-1.57079993 -0.00000007 0.02002297"/>
    <parent link="R_shoulder_yaw_link"/>
    <child link="R_elbow_roll_link"/>
    <axis xyz="0 0 1"/>
    <limit lower="-2.65289993" upper="0.0349" velocity="3.14159984"/>
    <dynamics friction="0"/>
    <!-- isaac:source_drive {"armature": 0.0, "drive": {"damping": 3.0, "max_force": 45.0, "stiffness": 300.0, "target_position": 0.0}, "instance": "angular", "source": "physx"} -->
  </joint>
  <joint name="L_elbow_yaw_joint" type="revolute">
    <origin xyz="0.019993 -0.10368001 0" rpy="1.5708 -0.0000001 0.00000001"/>
    <parent link="L_elbow_roll_link"/>
    <child link="L_elbow_yaw_link"/>
    <axis xyz="0 0 1"/>
    <limit lower="-2.93219975" upper="2.93219975" velocity="3.14159984"/>
    <dynamics friction="0"/>
    <!-- isaac:source_drive {"armature": 0.0, "drive": {"damping": 3.0, "max_force": 20.0, "stiffness": 300.0, "target_position": 0.0}, "instance": "angular", "source": "physx"} -->
  </joint>
  <joint name="R_elbow_yaw_joint" type="revolute">
    <origin xyz="0.019993 -0.10368 -0" rpy="1.57080001 0.00000005 -0.00000002"/>
    <parent link="R_elbow_roll_link"/>
    <child link="R_elbow_yaw_link"/>
    <axis xyz="0 0 1"/>
    <limit lower="-2.93219975" upper="2.93219975" velocity="3.14159984"/>
    <dynamics friction="0"/>
    <!-- isaac:source_drive {"armature": 0.0, "drive": {"damping": 3.0, "max_force": 20.0, "stiffness": 300.0, "target_position": 0.0}, "instance": "angular", "source": "physx"} -->
  </joint>
  <joint name="L_wrist_pitch_joint" type="revolute">
    <origin xyz="-0.00000001 -0.00000001 0.11832003" rpy="-0.0084397 1.57079263 3.13314562"/>
    <parent link="L_elbow_yaw_link"/>
    <child link="L_wrist_pitch_link"/>
    <axis xyz="0 0 1"/>
    <limit lower="-1.65799994" upper="1.65799994" velocity="3.14159984"/>
    <dynamics friction="0"/>
    <!-- isaac:source_drive {"armature": 0.0, "drive": {"damping": 3.0, "max_force": 20.0, "stiffness": 300.0, "target_position": 0.0}, "instance": "angular", "source": "physx"} -->
  </joint>
  <joint name="R_wrist_pitch_joint" type="revolute">
    <origin xyz="-0.00000001 0 0.11832001" rpy="0.02126012 1.57079271 -3.12033979"/>
    <parent link="R_elbow_yaw_link"/>
    <child link="R_wrist_pitch_link"/>
    <axis xyz="0 0 1"/>
    <limit lower="-1.65799994" upper="1.65799994" velocity="3.14159984"/>
    <dynamics friction="0"/>
    <!-- isaac:source_drive {"armature": 0.0, "drive": {"damping": 3.0, "max_force": 20.0, "stiffness": 300.0, "target_position": 0.0}, "instance": "angular", "source": "physx"} -->
  </joint>
  <joint name="L_wrist_roll_joint" type="revolute">
    <origin xyz="-0.076 0 0.00000003" rpy="-1.58714191 1.57079286 -0.01634208"/>
    <parent link="L_wrist_pitch_link"/>
    <child link="L_wrist_roll_link"/>
    <axis xyz="0 0 1"/>
    <limit lower="-2.02449977" upper="2.02449977" velocity="3.14159984"/>
    <dynamics friction="0"/>
    <!-- isaac:source_drive {"armature": 0.0, "drive": {"damping": 3.0, "max_force": 20.0, "stiffness": 300.0, "target_position": 0.0}, "instance": "angular", "source": "physx"} -->
  </joint>
  <joint name="R_wrist_roll_joint" type="revolute">
    <origin xyz="-0.076 -0 0" rpy="-1.53688215 1.57079276 0.0339178"/>
    <parent link="R_wrist_pitch_link"/>
    <child link="R_wrist_roll_link"/>
    <axis xyz="0 0 1"/>
    <limit lower="-2.02449977" upper="2.02449977" velocity="3.14159984"/>
    <dynamics friction="0"/>
    <!-- isaac:source_drive {"armature": 0.0, "drive": {"damping": 3.0, "max_force": 20.0, "stiffness": 300.0, "target_position": 0.0}, "instance": "angular", "source": "physx"} -->
  </joint>
  <joint name="L_sixforce_joint" type="fixed">
    <origin xyz="0.00000004 0.07712003 0.00000002" rpy="-3.14159251 0.0000036 1.57079232"/>
    <parent link="L_wrist_roll_link"/>
    <child link="L_sixforce_link"/>
  </joint>
  <joint name="R_sixforce_joint" type="fixed">
    <origin xyz="0 0.07712002 -0" rpy="0.00000359 -0.00000017 1.57080001"/>
    <parent link="R_wrist_roll_link"/>
    <child link="R_sixforce_link"/>
  </joint>
  <joint name="AssemblerFixedJoint" type="fixed">
    <origin xyz="0.00000004 0.00000001 0.00000001" rpy="0 1.57079601 -0.00000019"/>
    <parent link="L_sixforce_link"/>
    <child link="L_hand_base_link"/>
  </joint>
  <joint name="AssemblerFixedJoint" type="fixed">
    <origin xyz="0.00000001 0.00000001 -0.00000001" rpy="0 -1.5707962 3.1415926"/>
    <parent link="R_sixforce_link"/>
    <child link="R_hand_base_link"/>
  </joint>
  <joint name="L_palm_joint" type="fixed">
    <origin xyz="0.00035572 -0.013196 0.099778" rpy="-1.57159879 -1.57079263 -3.14078649"/>
    <parent link="L_hand_base_link"/>
    <child link="L_palm_link"/>
  </joint>
  <joint name="R_palm_joint" type="fixed">
    <origin xyz="0.00035702 -0.013196 0.099778" rpy="-1.57079448 -1.57079263 -3.14159081"/>
    <parent link="R_hand_base_link"/>
    <child link="R_palm_link"/>
  </joint>
  <joint name="L_thumb_cmp_joint" type="revolute">
    <origin xyz="-0.048578 0.028956 -0.0073648" rpy="-1.57080007 -0.75224003 1.57080007"/>
    <parent link="L_palm_link"/>
    <child link="L_thumb_cmp_link"/>
    <axis xyz="0 0 1"/>
    <limit lower="-0.96" upper="0" effort="1.35000002" velocity="2.08999991"/>
    <dynamics friction="0"/>
    <!-- isaac:source_drive {"armature": 0.0, "drive": {"damping": 0.0, "max_force": 1.350000023841858, "stiffness": 0.0, "target_position": 0.0}, "instance": "angular", "source": "physx"} -->
  </joint>
  <joint name="L_index_mpp_joint" type="revolute">
    <origin xyz="0.041817 0.030769 -0.011696" rpy="1.57079998 -0.18118001 0.020071"/>
    <parent link="L_palm_link"/>
    <child link="L_index_mpp_link"/>
    <axis xyz="0 0 1"/>
    <limit lower="0" upper="1.46000004" effort="1.35000002" velocity="2.08999991"/>
    <dynamics friction="0"/>
    <!-- isaac:source_drive {"armature": 0.0, "drive": {"damping": 0.0, "max_force": 1.350000023841858, "stiffness": 0.0, "target_position": 0.0}, "instance": "angular", "source": "physx"} -->
  </joint>
  <joint name="L_middle_mpp_joint" type="revolute">
    <origin xyz="0.042022 0.010356 -0.011696" rpy="1.57080005 -0.18118 -0"/>
    <parent link="L_palm_link"/>
    <child link="L_middle_mpp_link"/>
    <axis xyz="0 0 1"/>
    <limit lower="0" upper="1.46000004" effort="1.35000002" velocity="2.08999991"/>
    <dynamics friction="0"/>
    <!-- isaac:source_drive {"armature": 0.0, "drive": {"damping": 0.0, "max_force": 1.350000023841858, "stiffness": 0.0, "target_position": 0.0}, "instance": "angular", "source": "physx"} -->
  </joint>
  <joint name="L_ring_mpp_joint" type="revolute">
    <origin xyz="0.041817 -0.010057 -0.011696" rpy="1.57080007 -0.18117998 -0.02007102"/>
    <parent link="L_palm_link"/>
    <child link="L_ring_mpp_link"/>
    <axis xyz="0 0 1"/>
    <limit lower="0" upper="1.46000004" effort="1.35000002" velocity="2.08999991"/>
    <dynamics friction="0"/>
    <!-- isaac:source_drive {"armature": 0.0, "drive": {"damping": 0.0, "max_force": 1.350000023841858, "stiffness": 0.0, "target_position": 0.0}, "instance": "angular", "source": "physx"} -->
  </joint>
  <joint name="L_little_mpp_joint" type="revolute">
    <origin xyz="0.041203 -0.030462 -0.011696" rpy="1.57079995 -0.18118 -0.040143"/>
    <parent link="L_palm_link"/>
    <child link="L_little_mpp_link"/>
    <axis xyz="0 0 1"/>
    <limit lower="0" upper="1.46000004" effort="1.35000002" velocity="2.08999991"/>
    <dynamics friction="0"/>
    <!-- isaac:source_drive {"armature": 0.0, "drive": {"damping": 0.0, "max_force": 1.350000023841858, "stiffness": 0.0, "target_position": 0.0}, "instance": "angular", "source": "physx"} -->
  </joint>
  <joint name="R_thumb_cmp_joint" type="revolute">
    <origin xyz="-0.048578 -0.028956 -0.0073648" rpy="1.57080007 -0.75224003 -1.57080007"/>
    <parent link="R_palm_link"/>
    <child link="R_thumb_cmp_link"/>
    <axis xyz="0 0 1"/>
    <limit lower="0" upper="0.96" effort="1.35000002" velocity="2.08999991"/>
    <dynamics friction="0"/>
    <!-- isaac:source_drive {"armature": 0.0, "drive": {"damping": 0.0, "max_force": 1.350000023841858, "stiffness": 0.0, "target_position": 0.0}, "instance": "angular", "source": "physx"} -->
  </joint>
  <joint name="R_index_mpp_joint" type="revolute">
    <origin xyz="0.041818 -0.03077 -0.011696" rpy="1.57080007 -0.18117998 -0.02007102"/>
    <parent link="R_palm_link"/>
    <child link="R_index_mpp_link"/>
    <axis xyz="0 0 1"/>
    <limit lower="0" upper="1.46000004" effort="1.35000002" velocity="2.08999991"/>
    <dynamics friction="0"/>
    <!-- isaac:source_drive {"armature": 0.0, "drive": {"damping": 0.0, "max_force": 1.350000023841858, "stiffness": 0.0, "target_position": 0.0}, "instance": "angular", "source": "physx"} -->
  </joint>
  <joint name="R_middle_mpp_joint" type="revolute">
    <origin xyz="0.042022 -0.011107 -0.011696" rpy="1.56729996 -0.18114001 0.01967801"/>
    <parent link="R_palm_link"/>
    <child link="R_middle_mpp_link"/>
    <axis xyz="0 0 1"/>
    <limit lower="0" upper="1.46000004" effort="1.35000002" velocity="2.08999991"/>
    <dynamics friction="0"/>
    <!-- isaac:source_drive {"armature": 0.0, "drive": {"damping": 0.0, "max_force": 1.350000023841858, "stiffness": 0.0, "target_position": 0.0}, "instance": "angular", "source": "physx"} -->
  </joint>
  <joint name="R_ring_mpp_joint" type="revolute">
    <origin xyz="0.041818 0.010057 -0.011696" rpy="1.57079998 -0.18118001 0.020071"/>
    <parent link="R_palm_link"/>
    <child link="R_ring_mpp_link"/>
    <axis xyz="0 0 1"/>
    <limit lower="0" upper="1.46000004" effort="1.35000002" velocity="2.08999991"/>
    <dynamics friction="0"/>
    <!-- isaac:source_drive {"armature": 0.0, "drive": {"damping": 0.0, "max_force": 1.350000023841858, "stiffness": 0.0, "target_position": 0.0}, "instance": "angular", "source": "physx"} -->
  </joint>
  <joint name="R_little_mpp_joint" type="revolute">
    <origin xyz="0.041203 0.030462 -0.011696" rpy="1.57080007 -0.18118 0.040143"/>
    <parent link="R_palm_link"/>
    <child link="R_little_mpp_link"/>
    <axis xyz="0 0 1"/>
    <limit lower="0" upper="1.46000004" effort="1.35000002" velocity="2.08999991"/>
    <dynamics friction="0"/>
    <!-- isaac:source_drive {"armature": 0.0, "drive": {"damping": 0.0, "max_force": 1.350000023841858, "stiffness": 0.0, "target_position": 0.0}, "instance": "angular", "source": "physx"} -->
  </joint>
  <joint name="L_thumb_mpp_joint" type="revolute">
    <origin xyz="0.012 -0.0010557 -0.010045" rpy="-1.67549998 0.00000001 0.00000005"/>
    <parent link="L_thumb_cmp_link"/>
    <child link="L_thumb_mpp_link"/>
    <axis xyz="0 0 1"/>
    <limit lower="0" upper="1.04000003" effort="1.35000002" velocity="2.08999991"/>
    <dynamics friction="0"/>
    <!-- isaac:source_drive {"armature": 0.0, "drive": {"damping": 0.0, "max_force": 1.350000023841858, "stiffness": 0.0, "target_position": 0.0}, "instance": "angular", "source": "physx"} -->
  </joint>
  <joint name="L_index_ip_joint" type="revolute">
    <origin xyz="0.0388 -0 0" rpy="0.00000008 -0.00000001 -0.01450125"/>
    <parent link="L_index_mpp_link"/>
    <child link="L_index_ip_link"/>
    <axis xyz="0 0 1"/>
    <limit lower="0" upper="1.61999996" effort="1.35000002" velocity="2.08999991"/>
    <dynamics friction="0"/>
    <!-- isaac:source_drive {"armature": 0.0, "drive": {"damping": 0.0, "max_force": 1.350000023841858, "stiffness": 0.0, "target_position": 0.0}, "instance": "angular", "source": "physx"} -->
  </joint>
  <joint name="L_middle_ip_joint" type="revolute">
    <origin xyz="0.0388 -0 -0" rpy="0.00000003 0 -0.01205968"/>
    <parent link="L_middle_mpp_link"/>
    <child link="L_middle_ip_link"/>
    <axis xyz="0 0 1"/>
    <limit lower="0" upper="1.61999996" effort="1.35000002" velocity="2.08999991"/>
    <dynamics friction="0"/>
    <!-- isaac:source_drive {"armature": 0.0, "drive": {"damping": 0.0, "max_force": 1.350000023841858, "stiffness": 0.0, "target_position": 0.0}, "instance": "angular", "source": "physx"} -->
  </joint>
  <joint name="L_ring_ip_joint" type="revolute">
    <origin xyz="0.0388 -0 -0" rpy="-0.0000001 0.00000001 -0.01450124"/>
    <parent link="L_ring_mpp_link"/>
    <child link="L_ring_ip_link"/>
    <axis xyz="0 0 1"/>
    <limit lower="0" upper="1.61999996" effort="1.35000002" velocity="2.08999991"/>
    <dynamics friction="0"/>
    <!-- isaac:source_drive {"armature": 0.0, "drive": {"damping": 0.0, "max_force": 1.350000023841858, "stiffness": 0.0, "target_position": 0.0}, "instance": "angular", "source": "physx"} -->
  </joint>
  <joint name="L_little_ip_joint" type="revolute">
    <origin xyz="0.0388 -0 -0" rpy="-0.00000002 0 -0.01450124"/>
    <parent link="L_little_mpp_link"/>
    <child link="L_little_ip_link"/>
    <axis xyz="0 0 1"/>
    <limit lower="0" upper="1.61999996" effort="1.35000002" velocity="2.08999991"/>
    <dynamics friction="0"/>
    <!-- isaac:source_drive {"armature": 0.0, "drive": {"damping": 0.0, "max_force": 1.350000023841858, "stiffness": 0.0, "target_position": 0.0}, "instance": "angular", "source": "physx"} -->
  </joint>
  <joint name="R_thumb_mpp_joint" type="revolute">
    <origin xyz="0.012 0.0010557 -0.010045" rpy="-1.46609986 -0.00015421 -0.00001626"/>
    <parent link="R_thumb_cmp_link"/>
    <child link="R_thumb_mpp_link"/>
    <axis xyz="0 0 1"/>
    <limit lower="0" upper="1.04000003" effort="1.35000002" velocity="2.08999991"/>
    <dynamics friction="0"/>
    <!-- isaac:source_drive {"armature": 0.0, "drive": {"damping": 0.0, "max_force": 1.350000023841858, "stiffness": 0.0, "target_position": 0.0}, "instance": "angular", "source": "physx"} -->
  </joint>
  <joint name="R_index_ip_joint" type="revolute">
    <origin xyz="0.0388 -0 -0" rpy="-0.0000001 0.00000001 -0.01450124"/>
    <parent link="R_index_mpp_link"/>
    <child link="R_index_ip_link"/>
    <axis xyz="0 0 1"/>
    <limit lower="0" upper="1.61999996" effort="1.35000002" velocity="2.08999991"/>
    <dynamics friction="0"/>
    <!-- isaac:source_drive {"armature": 0.0, "drive": {"damping": 0.0, "max_force": 1.350000023841858, "stiffness": 0.0, "target_position": 0.0}, "instance": "angular", "source": "physx"} -->
  </joint>
  <joint name="R_middle_ip_joint" type="revolute">
    <origin xyz="0.038807 -0 0" rpy="0.00023365 -0.01935448 -0.0120683"/>
    <parent link="R_middle_mpp_link"/>
    <child link="R_middle_ip_link"/>
    <axis xyz="0 0 1"/>
    <limit lower="0" upper="1.61999996" effort="1.35000002" velocity="2.08999991"/>
    <dynamics friction="0"/>
    <!-- isaac:source_drive {"armature": 0.0, "drive": {"damping": 0.0, "max_force": 1.350000023841858, "stiffness": 0.0, "target_position": 0.0}, "instance": "angular", "source": "physx"} -->
  </joint>
  <joint name="R_ring_ip_joint" type="revolute">
    <origin xyz="0.0388 -0 0" rpy="0.00000008 -0.00000001 -0.01450125"/>
    <parent link="R_ring_mpp_link"/>
    <child link="R_ring_ip_link"/>
    <axis xyz="0 0 1"/>
    <limit lower="0" upper="1.61999996" effort="1.35000002" velocity="2.08999991"/>
    <dynamics friction="0"/>
    <!-- isaac:source_drive {"armature": 0.0, "drive": {"damping": 0.0, "max_force": 1.350000023841858, "stiffness": 0.0, "target_position": 0.0}, "instance": "angular", "source": "physx"} -->
  </joint>
  <joint name="R_little_ip_joint" type="revolute">
    <origin xyz="0.0388 -0 0" rpy="-0.00000009 0.00000001 -0.01450125"/>
    <parent link="R_little_mpp_link"/>
    <child link="R_little_ip_link"/>
    <axis xyz="0 0 1"/>
    <limit lower="0" upper="1.61999996" effort="1.35000002" velocity="2.08999991"/>
    <dynamics friction="0"/>
    <!-- isaac:source_drive {"armature": 0.0, "drive": {"damping": 0.0, "max_force": 1.350000023841858, "stiffness": 0.0, "target_position": 0.0}, "instance": "angular", "source": "physx"} -->
  </joint>
  <joint name="L_thumb_ip_joint" type="revolute">
    <origin xyz="0.075 -0.00001163 0" rpy="-0.00000003 0 0"/>
    <parent link="L_thumb_mpp_link"/>
    <child link="L_thumb_ip_link"/>
    <axis xyz="0 0 1"/>
    <limit lower="0" upper="1.05" effort="1.35000002" velocity="2.08999991"/>
    <dynamics friction="0"/>
    <!-- isaac:source_drive {"armature": 0.0, "drive": {"damping": 0.0, "max_force": 1.350000023841858, "stiffness": 0.0, "target_position": 0.0}, "instance": "angular", "source": "physx"} -->
  </joint>
  <joint name="R_thumb_ip_joint" type="revolute">
    <origin xyz="0.075 -0 0" rpy="-0.00000009 0 0.01207943"/>
    <parent link="R_thumb_mpp_link"/>
    <child link="R_thumb_ip_link"/>
    <axis xyz="0 0 1"/>
    <limit lower="0" upper="1.05" effort="1.35000002" velocity="2.08999991"/>
    <dynamics friction="0"/>
    <!-- isaac:source_drive {"armature": 0.0, "drive": {"damping": 0.0, "max_force": 1.350000023841858, "stiffness": 0.0, "target_position": 0.0}, "instance": "angular", "source": "physx"} -->
  </joint>
</robot>
