<mujoco model="walker_s2_description">
  <compiler angle="radian" meshdir="assets/" />
  <asset>
    <mesh name="s2_base_link" file="s2/base_link.STL" />
    <mesh name="s2_waist_yaw_link" file="s2/waist_yaw_link.STL" />
    <mesh name="s2_waist_pitch_link" file="s2/waist_pitch_link.STL" />
    <mesh name="s2_head_yaw_link" file="s2/head_yaw_link.STL" />
    <mesh name="s2_head_pitch_link" file="s2/head_pitch_link.STL" />
    <mesh name="s2_L_shoulder_pitch_link" file="s2/L_shoulder_pitch_link.STL" />
    <mesh name="s2_L_shoulder_roll_link" file="s2/L_shoulder_roll_link.STL" />
    <mesh name="s2_L_shoulder_yaw_link" file="s2/L_shoulder_yaw_link.STL" />
    <mesh name="s2_L_elbow_roll_link" file="s2/L_elbow_roll_link.STL" />
    <mesh name="s2_L_elbow_yaw_link" file="s2/L_elbow_yaw_link.STL" />
    <mesh name="s2_L_wrist_pitch_link" file="s2/L_wrist_pitch_link.STL" />
    <mesh name="s2_L_wrist_roll_link" file="s2/L_wrist_roll_link.STL" />
    <mesh name="s2_L_sixforce_link" file="s2/L_sixforce_link.STL" />
    <mesh name="s2_R_shoulder_pitch_link" file="s2/R_shoulder_pitch_link.STL" />
    <mesh name="s2_R_shoulder_roll_link" file="s2/R_shoulder_roll_link.STL" />
    <mesh name="s2_R_shoulder_yaw_link" file="s2/R_shoulder_yaw_link.STL" />
    <mesh name="s2_R_elbow_roll_link" file="s2/R_elbow_roll_link.STL" />
    <mesh name="s2_R_elbow_yaw_link" file="s2/R_elbow_yaw_link.STL" />
    <mesh name="s2_R_wrist_pitch_link" file="s2/R_wrist_pitch_link.STL" />
    <mesh name="s2_R_wrist_roll_link" file="s2/R_wrist_roll_link.STL" />
    <mesh name="s2_R_sixforce_link" file="s2/R_sixforce_link.STL" />
    <mesh name="s2_L_hip_roll_link" file="s2/L_hip_roll_link.STL" />
    <mesh name="s2_L_hip_yaw_link" file="s2/L_hip_yaw_link.STL" />
    <mesh name="s2_L_hip_pitch_link" file="s2/L_hip_pitch_link.STL" />
    <mesh name="s2_L_knee_pitch_link" file="s2/L_knee_pitch_link.STL" />
    <mesh name="s2_L_ankle_pitch_link" file="s2/L_ankle_pitch_link.STL" />
    <mesh name="s2_L_ankle_roll_link" file="s2/L_ankle_roll_link.STL" />
    <mesh name="s2_R_hip_roll_link" file="s2/R_hip_roll_link.STL" />
    <mesh name="s2_R_hip_yaw_link" file="s2/R_hip_yaw_link.STL" />
    <mesh name="s2_R_hip_pitch_link" file="s2/R_hip_pitch_link.STL" />
    <mesh name="s2_R_knee_pitch_link" file="s2/R_knee_pitch_link.STL" />
    <mesh name="s2_R_ankle_pitch_link" file="s2/R_ankle_pitch_link.STL" />
    <mesh name="s2_R_ankle_roll_link" file="s2/R_ankle_roll_link.STL" />
    <mesh name="hand3_v1_L_hand_base_link" file="hand3_v1/L_hand_base_link.STL" />
    <mesh name="hand3_v1_L_palm_link" file="hand3_v1/L_palm_link.STL" />
    <mesh name="hand3_v1_L_thumb_cmp_link" file="hand3_v1/L_thumb_cmp_link.STL" />
    <mesh name="hand3_v1_L_thumb_mpp_link" file="hand3_v1/L_thumb_mpp_link.STL" />
    <mesh name="hand3_v1_L_thumb_ip_link" file="hand3_v1/L_thumb_ip_link.STL" />
    <mesh name="hand3_v1_L_index_mpp_link" file="hand3_v1/L_index_mpp_link.STL" />
    <mesh name="hand3_v1_L_index_ip_link" file="hand3_v1/L_index_ip_link.STL" />
    <mesh name="hand3_v1_L_middle_mpp_link" file="hand3_v1/L_middle_mpp_link.STL" />
    <mesh name="hand3_v1_L_middle_ip_link" file="hand3_v1/L_middle_ip_link.STL" />
    <mesh name="hand3_v1_L_ring_mpp_link" file="hand3_v1/L_ring_mpp_link.STL" />
    <mesh name="hand3_v1_L_ring_ip_link" file="hand3_v1/L_ring_ip_link.STL" />
    <mesh name="hand3_v1_L_little_mpp_link" file="hand3_v1/L_little_mpp_link.STL" />
    <mesh name="hand3_v1_L_little_ip_link" file="hand3_v1/L_little_ip_link.STL" />
    <mesh name="hand3_v1_R_hand_base_link" file="hand3_v1/R_hand_base_link.STL" />
    <mesh name="hand3_v1_R_palm_link" file="hand3_v1/R_palm_link.STL" />
    <mesh name="hand3_v1_R_thumb_cmp_link" file="hand3_v1/R_thumb_cmp_link.STL" />
    <mesh name="hand3_v1_R_thumb_mpp_link" file="hand3_v1/R_thumb_mpp_link.STL" />
    <mesh name="hand3_v1_R_thumb_ip_link" file="hand3_v1/R_thumb_ip_link.STL" />
    <mesh name="hand3_v1_R_index_mpp_link" file="hand3_v1/R_index_mpp_link.STL" />
    <mesh name="hand3_v1_R_index_ip_link" file="hand3_v1/R_index_ip_link.STL" />
    <mesh name="hand3_v1_R_middle_mpp_link" file="hand3_v1/R_middle_mpp_link.STL" />
    <mesh name="hand3_v1_R_middle_ip_link" file="hand3_v1/R_middle_ip_link.STL" />
    <mesh name="hand3_v1_R_ring_mpp_link" file="hand3_v1/R_ring_mpp_link.STL" />
    <mesh name="hand3_v1_R_ring_ip_link" file="hand3_v1/R_ring_ip_link.STL" />
    <mesh name="hand3_v1_R_little_mpp_link" file="hand3_v1/R_little_mpp_link.STL" />
    <mesh name="hand3_v1_R_little_ip_link" file="hand3_v1/R_little_ip_link.STL" />
    <material name="base_link_mat" rgba="1 1 1 1" specular="0" />
    <material name="waist_yaw_link_mat" rgba="1 1 1 1" specular="0" />
    <material name="waist_pitch_link_mat" rgba="1 1 1 1" specular="0" />
    <material name="head_yaw_link_mat" rgba="1 1 1 1" specular="0" />
    <material name="head_pitch_link_mat" rgba="1 1 1 1" specular="0" />
    <material name="L_shoulder_pitch_link_mat" rgba="1 1 1 1" specular="0" />
    <material name="L_shoulder_roll_link_mat" rgba="1 1 1 1" specular="0" />
    <material name="L_shoulder_yaw_link_mat" rgba="1 1 1 1" specular="0" />
    <material name="L_elbow_roll_link_mat" rgba="1 1 1 1" specular="0" />
    <material name="L_elbow_yaw_link_mat" rgba="1 1 1 1" specular="0" />
    <material name="L_wrist_pitch_link_mat" rgba="1 1 1 1" specular="0" />
    <material name="L_wrist_roll_link_mat" rgba="1 1 1 1" specular="0" />
    <material name="L_sixforce_link_mat" rgba="1 1 1 1" specular="0" />
    <material name="R_shoulder_pitch_link_mat" rgba="1 1 1 1" specular="0" />
    <material name="R_shoulder_roll_link_mat" rgba="1 1 1 1" specular="0" />
    <material name="R_shoulder_yaw_link_mat" rgba="1 1 1 1" specular="0" />
    <material name="R_elbow_roll_link_mat" rgba="1 1 1 1" specular="0" />
    <material name="R_elbow_yaw_link_mat" rgba="1 1 1 1" specular="0" />
    <material name="R_wrist_pitch_link_mat" rgba="1 1 1 1" specular="0" />
    <material name="R_wrist_roll_link_mat" rgba="1 1 1 1" specular="0" />
    <material name="R_sixforce_link_mat" rgba="1 1 1 1" specular="0" />
    <material name="L_hip_roll_link_mat" rgba="1 1 1 1" specular="0" />
    <material name="L_hip_yaw_link_mat" rgba="1 1 1 1" specular="0" />
    <material name="L_hip_pitch_link_mat" rgba="1 1 1 1" specular="0" />
    <material name="L_knee_pitch_link_mat" rgba="1 1 1 1" specular="0" />
    <material name="L_ankle_pitch_link_mat" rgba="1 1 1 1" specular="0" />
    <material name="L_ankle_roll_link_mat" rgba="1 1 1 1" specular="0" />
    <material name="R_hip_roll_link_mat" rgba="1 1 1 1" specular="0" />
    <material name="R_hip_yaw_link_mat" rgba="1 1 1 1" specular="0" />
    <material name="R_hip_pitch_link_mat" rgba="1 1 1 1" specular="0" />
    <material name="R_knee_pitch_link_mat" rgba="1 1 1 1" specular="0" />
    <material name="R_ankle_pitch_link_mat" rgba="1 1 1 1" specular="0" />
    <material name="R_ankle_roll_link_mat" rgba="1 1 1 1" specular="0" />
    <material name="hand3_v1_left_mat" rgba="0.7922 0.8196 0.9333 1" specular="0" />
    <material name="hand3_v1_left_L_palm_link_mat" rgba="1 1 1 1" specular="0" />
    <material name="hand3_v1_left_L_thumb_cmp_link_mat" rgba="0.7529 0.7529 0.7529 1" specular="0" />
    <material name="hand3_v1_left_L_thumb_mpp_link_mat" rgba="0.7529 0.7529 0.7529 1" specular="0" />
    <material name="hand3_v1_left_L_thumb_ip_link_mat" rgba="0.7529 0.7529 0.7529 1" specular="0" />
    <material name="hand3_v1_left_L_index_mpp_link_mat" rgba="0.7529 0.7529 0.7529 1" specular="0" />
    <material name="hand3_v1_left_L_index_ip_link_mat" rgba="0.7529 0.7529 0.7529 1" specular="0" />
    <material name="hand3_v1_left_L_middle_mpp_link_mat" rgba="0.7529 0.7529 0.7529 1" specular="0" />
    <material name="hand3_v1_left_L_middle_ip_link_mat" rgba="0.7529 0.7529 0.7529 1" specular="0" />
    <material name="hand3_v1_left_L_ring_mpp_link_mat" rgba="0.7529 0.7529 0.7529 1" specular="0" />
    <material name="hand3_v1_left_L_ring_ip_link_mat" rgba="0.7529 0.7529 0.7529 1" specular="0" />
    <material name="hand3_v1_left_L_little_mpp_link_mat" rgba="0.7529 0.7529 0.7529 1" specular="0" />
    <material name="hand3_v1_left_L_little_ip_link_mat" rgba="0.7529 0.7529 0.7529 1" specular="0" />
    <material name="hand3_v1_right_mat" rgba="0.7922 0.8196 0.9333 1" specular="0" />
    <material name="hand3_v1_right_R_palm_link_mat" rgba="0.7529 0.7529 0.7529 1" specular="0" />
    <material name="hand3_v1_right_R_thumb_cmp_link_mat" rgba="0.7529 0.7529 0.7529 1" specular="0" />
    <material name="hand3_v1_right_R_thumb_mpp_link_mat" rgba="0.7529 0.7529 0.7529 1" specular="0" />
    <material name="hand3_v1_right_R_thumb_ip_link_mat" rgba="0.7529 0.7529 0.7529 1" specular="0" />
    <material name="hand3_v1_right_R_index_mpp_link_mat" rgba="0.7529 0.7529 0.7529 1" specular="0" />
    <material name="hand3_v1_right_R_index_ip_link_mat" rgba="0.7529 0.7529 0.7529 1" specular="0" />
    <material name="hand3_v1_right_R_middle_mpp_link_mat" rgba="0.7529 0.7529 0.7529 1" specular="0" />
    <material name="hand3_v1_right_R_middle_ip_link_mat" rgba="0.7529 0.7529 0.7529 1" specular="0" />
    <material name="hand3_v1_right_R_ring_mpp_link_mat" rgba="0.7529 0.7529 0.7529 1" specular="0" />
    <material name="hand3_v1_right_R_ring_ip_link_mat" rgba="0.7529 0.7529 0.7529 1" specular="0" />
    <material name="hand3_v1_right_R_little_mpp_link_mat" rgba="0.7529 0.7529 0.7529 1" specular="0" />
    <material name="hand3_v1_right_R_little_ip_link_mat" rgba="0.7529 0.7529 0.7529 1" specular="0" />
  </asset>

  <worldbody>
    <body name="base_link" pos="0 0 0">
      <inertial pos="-0.0638652 -0.0001135 0.0106526" mass="6.1056679" fullinertia="0.056248 0.0288325 0.0729667 -0.0000268 -0.0044323 -0.000134"/>
      <geom pos="0 0 0" group="1" contype="0" conaffinity="0" material="base_link_mat" type="mesh" mesh="s2_base_link" />
      <geom pos="0 0 0" rgba="0.9373 0.2667 0.2667 1" group="3" contype="1" conaffinity="1" type="mesh" mesh="s2_base_link" />
      <body name="waist_yaw_link" pos="-0.0009262 0 0.143" quat="-0.0000037 0.9999948 0 0.0032383">
        <joint name="waist_yaw_joint" type="hinge" axis="0 0 1" limited="true" range="-2.8274 2.8274" damping="0" frictionloss="0"/>
        <inertial pos="-0.0001989 -0.0096767 0.0271077" mass="0.5168399" fullinertia="0.0017193 0.0010836 0.0013879 0.0000024 0.0000096 -0.0000649"/>
        <geom pos="0 0 0" group="1" contype="0" conaffinity="0" material="waist_yaw_link_mat" type="mesh" mesh="s2_waist_yaw_link" />
        <geom pos="0 0 0" rgba="0.9373 0.2667 0.2667 1" group="3" contype="1" conaffinity="1" type="mesh" mesh="s2_waist_yaw_link" />
        <body name="waist_pitch_link" pos="0 0 0" quat="0.7071018 -0.7071044 -0.0022899 -0.0022899">
          <joint name="waist_pitch_joint" type="hinge" axis="0 0 1" limited="true" range="-1.5707 0.6108" damping="0" frictionloss="0"/>
          <inertial pos="-0.0173718 0.2054213 -0.0021071" mass="24.185886" fullinertia="0.5225492 0.2000245 0.4671002 0.0122 0.0024557 -0.00535"/>
          <geom pos="0 0 0" group="1" contype="0" conaffinity="0" material="waist_pitch_link_mat" type="mesh" mesh="s2_waist_pitch_link" />
          <geom pos="0 0 0" rgba="0.9373 0.2667 0.2667 1" group="3" contype="1" conaffinity="1" type="mesh" mesh="s2_waist_pitch_link" />
          <body name="head_yaw_link" pos="0 0.4841 0" quat="0.7071055 -0.7071081 0 0">
            <joint name="head_yaw_joint" type="hinge" axis="0 0 1" limited="true" range="-1.658 1.658" damping="0" frictionloss="0"/>
            <inertial pos="0.0002335 -0.0000398 0.0230805" mass="0.2195153" fullinertia="0.0000812 0.0000629 0.0000763 0.000001 -0.0000003 0.0000038"/>
            <geom pos="0 0 0" group="1" contype="0" conaffinity="0" material="head_yaw_link_mat" type="mesh" mesh="s2_head_yaw_link" />
            <geom pos="0 0 0" rgba="0.9373 0.2667 0.2667 1" group="3" contype="1" conaffinity="1" type="mesh" mesh="s2_head_yaw_link" />
            <body name="head_pitch_link" pos="0 0 0.025" quat="0.7071055 0.7071081 0 0">
              <joint name="head_pitch_joint" type="hinge" axis="0 0 1" limited="true" range="-0.7854 0.5236" damping="0" frictionloss="0"/>
              <inertial pos="0.0405655 0.1024969 -0.0002604" mass="1.0690069" fullinertia="0.0047354 0.0045081 0.0051857 0.0003344 -0.0000126 -0.0000268"/>
              <geom pos="0 0 0" group="1" contype="0" conaffinity="0" material="head_pitch_link_mat" type="mesh" mesh="s2_head_pitch_link" />
              <geom pos="0 0 0" rgba="0.9373 0.2667 0.2667 1" group="3" contype="1" conaffinity="1" type="mesh" mesh="s2_head_pitch_link" />
            </body>
          </body>
          <body name="L_shoulder_pitch_link" pos="-0.0046 0.34864 -0.15387" quat="0.7044148 0.0616275 -0.0616273 0.7044174">
            <joint name="L_shoulder_pitch_joint" type="hinge" axis="0 0 1" limited="true" range="-2.8623 2.8623" damping="0" frictionloss="0"/>
            <inertial pos="0.000221 -0.0050932 -0.0526295" mass="0.9814702" fullinertia="0.0011759 0.0011237 0.0009004 -0.0000048 -0.0000024 -0.0000312"/>
            <geom pos="0 0 0" group="1" contype="0" conaffinity="0" material="L_shoulder_pitch_link_mat" type="mesh" mesh="s2_L_shoulder_pitch_link" />
            <geom pos="0 0 0" rgba="0.9373 0.2667 0.2667 1" group="3" contype="1" conaffinity="1" type="mesh" mesh="s2_L_shoulder_pitch_link" />
            <body name="L_shoulder_roll_link" pos="0 0 -0.06" quat="0.7071055 -0.7071081 0 0">
              <joint name="L_shoulder_roll_joint" type="hinge" axis="0 0 1" limited="true" range="-1.885 0.1222" damping="0" frictionloss="0"/>
              <inertial pos="-0.0363463 0.0019751 -0.0052697" mass="0.5395701" fullinertia="0.0012305 0.0018915 0.0014298 -0.000019 0.000107 -0.000013"/>
              <geom pos="0 0 0" group="1" contype="0" conaffinity="0" material="L_shoulder_roll_link_mat" type="mesh" mesh="s2_L_shoulder_roll_link" />
              <geom pos="0 0 0" rgba="0.9373 0.2667 0.2667 1" group="3" contype="1" conaffinity="1" type="mesh" mesh="s2_L_shoulder_roll_link" />
              <body name="L_shoulder_yaw_link" pos="-0.083 0 0" quat="0.4999982 -0.5 -0.5000018 0.5">
                <joint name="L_shoulder_yaw_joint" type="hinge" axis="0 0 1" limited="true" range="-2.9322 2.9322" damping="0" frictionloss="0"/>
                <inertial pos="-0.00899 0.00278 0.1286019" mass="1.9975947" fullinertia="0.0156564 0.015768 0.0021057 0.000054 0.0015653 -0.000436"/>
                <geom pos="0 0 0" group="1" contype="0" conaffinity="0" material="L_shoulder_yaw_link_mat" type="mesh" mesh="s2_L_shoulder_yaw_link" />
                <geom pos="0 0 0" rgba="0.9373 0.2667 0.2667 1" group="3" contype="1" conaffinity="1" type="mesh" mesh="s2_L_shoulder_yaw_link" />
                <body name="L_elbow_roll_link" pos="-0.019993 0 0.213" quat="0.7071055 -0.7071081 0 0">
                  <joint name="L_elbow_roll_joint" type="hinge" axis="0 0 1" limited="true" range="-2.6529 0.0349" damping="0" frictionloss="0"/>
                  <inertial pos="0.0085304 -0.0574102 0.0008927" mass="0.667503" fullinertia="0.0025384 0.0013951 0.002205 0.0003061 0.0000075 -0.0000335"/>
                  <geom pos="0 0 0" group="1" contype="0" conaffinity="0" material="L_elbow_roll_link_mat" type="mesh" mesh="s2_L_elbow_roll_link" />
                  <geom pos="0 0 0" rgba="0.9373 0.2667 0.2667 1" group="3" contype="1" conaffinity="1" type="mesh" mesh="s2_L_elbow_roll_link" />
                  <body name="L_elbow_yaw_link" pos="0.019993 -0.10368 0" quat="0.7071055 0.7071081 0 0">
                    <joint name="L_elbow_yaw_joint" type="hinge" axis="0 0 1" limited="true" range="-2.9322 2.9322" damping="0" frictionloss="0"/>
                    <inertial pos="0.0009741 0.0001793 0.0457772" mass="0.8745749" fullinertia="0.0014384 0.0016363 0.0008758 0.0000039 -0.0000522 0.0000007"/>
                    <geom pos="0 0 0" group="1" contype="0" conaffinity="0" material="L_elbow_yaw_link_mat" type="mesh" mesh="s2_L_elbow_yaw_link" />
                    <geom pos="0 0 0" rgba="0.9373 0.2667 0.2667 1" group="3" contype="1" conaffinity="1" type="mesh" mesh="s2_L_elbow_yaw_link" />
                    <body name="L_wrist_pitch_link" pos="0 0 0.11832" quat="-0.0000026 0.7071055 -0.0000026 -0.7071081">
                      <joint name="L_wrist_pitch_joint" type="hinge" axis="0 0 1" limited="true" range="-1.658 1.658" damping="0" frictionloss="0"/>
                      <inertial pos="-0.0384446 -0.0048559 -0.004772" mass="1.3144509" fullinertia="0.0009004 0.0027314 0.0027358 -0.0002185 0.000227 0.0000305"/>
                      <geom pos="0 0 0" group="1" contype="0" conaffinity="0" material="L_wrist_pitch_link_mat" type="mesh" mesh="s2_L_wrist_pitch_link" />
                      <geom pos="0 0 0" rgba="0.9373 0.2667 0.2667 1" group="3" contype="1" conaffinity="1" type="mesh" mesh="s2_L_wrist_pitch_link" />
                      <body name="L_wrist_roll_link" pos="-0.076 0 0" quat="0.5 -0.5000018 0.4999982 0.5">
                        <joint name="L_wrist_roll_joint" type="hinge" axis="0 0 1" limited="true" range="-2.0245 2.0245" damping="0" frictionloss="0"/>
                        <inertial pos="-0.0000046 0.0170564 -0.0007487" mass="0.1521023" fullinertia="0.0002736 0.0002155 0.0001102 0 0 -0.0000077"/>
                        <geom pos="0 0 0" group="1" contype="0" conaffinity="0" material="L_wrist_roll_link_mat" type="mesh" mesh="s2_L_wrist_roll_link" />
                        <geom pos="0 0 0" rgba="0.9373 0.2667 0.2667 1" group="3" contype="1" conaffinity="1" type="mesh" mesh="s2_L_wrist_roll_link" />
                        <body name="L_sixforce_link" pos="0 0.07712 0" quat="0.4999982 -0.5000018 -0.5 -0.5">
                          <inertial pos="0.0001861 0.0000021 -0.0110656" mass="0.17" fullinertia="0.0000357 0.0000503 0.0000613 0.0000002 -0.0000008 0.0000001"/>
                          <geom pos="0 0 0" group="1" contype="0" conaffinity="0" material="L_sixforce_link_mat" type="mesh" mesh="s2_L_sixforce_link" />
                          <geom pos="0 0 0" rgba="0.9373 0.2667 0.2667 1" group="3" contype="1" conaffinity="1" type="mesh" mesh="s2_L_sixforce_link" />
                          <body name="hand3_v1_left" pos="0 0 0">
                            <inertial pos="0.0006593 0.0006466 0.0222316" mass="0.052387" fullinertia="0.0000172 0.0000368 0.0000401 0.0000003 -0.0000004 -0.0000002"/>
                            <geom pos="0 0 0" group="1" contype="0" conaffinity="0" material="hand3_v1_left_mat" type="mesh" mesh="hand3_v1_L_hand_base_link" />
                            <geom pos="0 0 0" rgba="0.9373 0.2667 0.2667 1" group="3" contype="1" conaffinity="1" type="mesh" mesh="hand3_v1_L_hand_base_link" />
                            <body name="hand3_v1_left_L_palm_link" pos="0.0003557 -0.013196 0.099778" quat="0.4999982 0.5 -0.5 0.5000018">
                              <inertial pos="-0.0093887 -0.002217 -0.0117814" mass="0.3822359" fullinertia="0.0002277 0.0003527 0.0005035 -0.0000017 0 -0.0000132"/>
                              <geom pos="0 0 0" group="1" contype="0" conaffinity="0" material="hand3_v1_left_L_palm_link_mat" type="mesh" mesh="hand3_v1_L_palm_link" />
                              <geom pos="0 0 0" rgba="0.9373 0.2667 0.2667 1" group="3" contype="1" conaffinity="1" type="mesh" mesh="hand3_v1_L_palm_link" />
                              <body name="hand3_v1_left_L_thumb_cmp_link" pos="-0.048578 0.028956 -0.0073648" quat="0.6487046 -0.2813912 -0.6487067 0.2813912">
                                <joint name="hand3_v1_left_L_thumb_cmp_joint" type="hinge" axis="0 0 1" limited="true" range="-0.96 0" damping="0" frictionloss="0"/>
                                <inertial pos="0.0056308 -0.00075 -0.0043585" mass="0.0151103" fullinertia="0.0000009 0.000001 0.0000011 0.0000001 0.0000003 0"/>
                                <geom pos="0 0 0" group="1" contype="0" conaffinity="0" material="hand3_v1_left_L_thumb_cmp_link_mat" type="mesh" mesh="hand3_v1_L_thumb_cmp_link" />
                                <geom pos="0 0 0" rgba="0.9373 0.2667 0.2667 1" group="3" contype="1" conaffinity="1" type="mesh" mesh="hand3_v1_L_thumb_cmp_link" />
                                <body name="hand3_v1_left_L_thumb_mpp_link" pos="0.012 -0.0010557 -0.010045" quat="0.6691366 -0.7431394 0 0">
                                  <joint name="hand3_v1_left_L_thumb_mpp_joint" type="hinge" axis="0 0 1" limited="true" range="0 1.04" damping="0" frictionloss="0"/>
                                  <inertial pos="0.0361842 -0.0019502 -0.000077" mass="0.067412" fullinertia="0.0000064 0.000033 0.0000327 -0.0000027 0 0"/>
                                  <geom pos="0 0 0" group="1" contype="0" conaffinity="0" material="hand3_v1_left_L_thumb_mpp_link_mat" type="mesh" mesh="hand3_v1_L_thumb_mpp_link" />
                                  <geom pos="0 0 0" rgba="0.9373 0.2667 0.2667 1" group="3" contype="1" conaffinity="1" type="mesh" mesh="hand3_v1_L_thumb_mpp_link" />
                                  <body name="hand3_v1_left_L_thumb_ip_link" pos="0.075 -0.0000116 0">
                                    <joint name="hand3_v1_left_L_thumb_ip_joint" type="hinge" axis="0 0 1" limited="true" range="0 1.05" damping="0" frictionloss="0"/>
                                    <inertial pos="0.0135371 0.0041693 0.0000061" mass="0.0173112" fullinertia="0.000001 0.0000019 0.0000018 -0.0000001 0 0"/>
                                    <geom pos="0 0 0" group="1" contype="0" conaffinity="0" material="hand3_v1_left_L_thumb_ip_link_mat" type="mesh" mesh="hand3_v1_L_thumb_ip_link" />
                                    <geom pos="0 0 0" rgba="0.9373 0.2667 0.2667 1" group="3" contype="1" conaffinity="1" type="mesh" mesh="hand3_v1_L_thumb_ip_link" />
                                  </body>
                                </body>
                              </body>
                              <body name="hand3_v1_left_L_index_mpp_link" pos="0.041817 0.030769 -0.011696" quat="0.7035286 0.7048151 -0.0568989 0.0710331">
                                <joint name="hand3_v1_left_L_index_mpp_joint" type="hinge" axis="0 0 1" limited="true" range="0 1.46" damping="0" frictionloss="0"/>
                                <inertial pos="0.0152531 -0.0018168 0.0001521" mass="0.0147008" diaginertia="0.0000009 0.0000036 0.0000035"/>
                                <geom pos="0 0 0" group="1" contype="0" conaffinity="0" material="hand3_v1_left_L_index_mpp_link_mat" type="mesh" mesh="hand3_v1_L_index_mpp_link" />
                                <geom pos="0 0 0" rgba="0.9373 0.2667 0.2667 1" group="3" contype="1" conaffinity="1" type="mesh" mesh="hand3_v1_L_index_mpp_link" />
                                <body name="hand3_v1_left_L_index_ip_link" pos="0.0388 0 0" quat="0.9999737 0 0 -0.0072544">
                                  <joint name="hand3_v1_left_L_index_ip_joint" type="hinge" axis="0 0 1" limited="true" range="0 1.62" damping="0" frictionloss="0"/>
                                  <inertial pos="0.0168086 -0.0011753 0" mass="0.0133493" fullinertia="0.0000004 0.0000026 0.0000026 -0.0000003 0 0"/>
                                  <geom pos="0 0 0" group="1" contype="0" conaffinity="0" material="hand3_v1_left_L_index_ip_link_mat" type="mesh" mesh="hand3_v1_L_index_ip_link" />
                                  <geom pos="0 0 0" rgba="0.9373 0.2667 0.2667 1" group="3" contype="1" conaffinity="1" type="mesh" mesh="hand3_v1_L_index_ip_link" />
                                </body>
                              </body>
                              <body name="hand3_v1_left_L_middle_mpp_link" pos="0.042022 0.010356 -0.011696" quat="0.704206 0.7042086 -0.0639691 0.0639693">
                                <joint name="hand3_v1_left_L_middle_mpp_joint" type="hinge" axis="0 0 1" limited="true" range="0 1.46" damping="0" frictionloss="0"/>
                                <inertial pos="0.0147601 -0.0017148 0.0001287" mass="0.0143021" diaginertia="0.0000009 0.0000034 0.0000034"/>
                                <geom pos="0 0 0" group="1" contype="0" conaffinity="0" material="hand3_v1_left_L_middle_mpp_link_mat" type="mesh" mesh="hand3_v1_L_middle_mpp_link" />
                                <geom pos="0 0 0" rgba="0.9373 0.2667 0.2667 1" group="3" contype="1" conaffinity="1" type="mesh" mesh="hand3_v1_L_middle_mpp_link" />
                                <body name="hand3_v1_left_L_middle_ip_link" pos="0.0388 0 0" quat="0.9999818 0 0 -0.006033">
                                  <joint name="hand3_v1_left_L_middle_ip_joint" type="hinge" axis="0 0 1" limited="true" range="0 1.62" damping="0" frictionloss="0"/>
                                  <inertial pos="0.0177132 -0.0010967 0.0000256" mass="0.0148881" fullinertia="0.0000005 0.0000034 0.0000034 -0.0000004 0 0"/>
                                  <geom pos="0 0 0" group="1" contype="0" conaffinity="0" material="hand3_v1_left_L_middle_ip_link_mat" type="mesh" mesh="hand3_v1_L_middle_ip_link" />
                                  <geom pos="0 0 0" rgba="0.9373 0.2667 0.2667 1" group="3" contype="1" conaffinity="1" type="mesh" mesh="hand3_v1_L_middle_ip_link" />
                                </body>
                              </body>
                              <body name="hand3_v1_left_L_ring_mpp_link" pos="0.041817 -0.010057 -0.011696" quat="0.7048125 0.7035312 -0.0710329 0.0568992">
                                <joint name="hand3_v1_left_L_ring_mpp_joint" type="hinge" axis="0 0 1" limited="true" range="0 1.46" damping="0" frictionloss="0"/>
                                <inertial pos="0.0147595 -0.001715 0.0001287" mass="0.0143021" diaginertia="0.0000009 0.0000034 0.0000034"/>
                                <geom pos="0 0 0" group="1" contype="0" conaffinity="0" material="hand3_v1_left_L_ring_mpp_link_mat" type="mesh" mesh="hand3_v1_L_ring_mpp_link" />
                                <geom pos="0 0 0" rgba="0.9373 0.2667 0.2667 1" group="3" contype="1" conaffinity="1" type="mesh" mesh="hand3_v1_L_ring_mpp_link" />
                                <body name="hand3_v1_left_L_ring_ip_link" pos="0.0388 0 0" quat="0.9999737 0 0 -0.0072544">
                                  <joint name="hand3_v1_left_L_ring_ip_joint" type="hinge" axis="0 0 1" limited="true" range="0 1.62" damping="0" frictionloss="0"/>
                                  <inertial pos="0.0161543 -0.0013024 0.0000276" mass="0.0137479" fullinertia="0.0000004 0.0000028 0.0000028 -0.0000003 0 0"/>
                                  <geom pos="0 0 0" group="1" contype="0" conaffinity="0" material="hand3_v1_left_L_ring_ip_link_mat" type="mesh" mesh="hand3_v1_L_ring_ip_link" />
                                  <geom pos="0 0 0" rgba="0.9373 0.2667 0.2667 1" group="3" contype="1" conaffinity="1" type="mesh" mesh="hand3_v1_L_ring_ip_link" />
                                </body>
                              </body>
                              <body name="hand3_v1_left_L_little_mpp_link" pos="0.041203 -0.030462 -0.011696" quat="0.705348 0.7027829 -0.0780898 0.0498229">
                                <joint name="hand3_v1_left_L_little_mpp_joint" type="hinge" axis="0 0 1" limited="true" range="0 1.46" damping="0" frictionloss="0"/>
                                <inertial pos="0.0147588 -0.0017151 0.0001287" mass="0.0143021" diaginertia="0.0000009 0.0000034 0.0000034"/>
                                <geom pos="0 0 0" group="1" contype="0" conaffinity="0" material="hand3_v1_left_L_little_mpp_link_mat" type="mesh" mesh="hand3_v1_L_little_mpp_link" />
                                <geom pos="0 0 0" rgba="0.9373 0.2667 0.2667 1" group="3" contype="1" conaffinity="1" type="mesh" mesh="hand3_v1_L_little_mpp_link" />
                                <body name="hand3_v1_left_L_little_ip_link" pos="0.0388 0 0" quat="0.9999737 0 0 -0.0072544">
                                  <joint name="hand3_v1_left_L_little_ip_joint" type="hinge" axis="0 0 1" limited="true" range="0 1.62" damping="0" frictionloss="0"/>
                                  <inertial pos="0.0130333 -0.0014344 0.0000295" mass="0.0117927" fullinertia="0.0000003 0.0000018 0.0000018 -0.0000002 0 0"/>
                                  <geom pos="0 0 0" group="1" contype="0" conaffinity="0" material="hand3_v1_left_L_little_ip_link_mat" type="mesh" mesh="hand3_v1_L_little_ip_link" />
                                  <geom pos="0 0 0" rgba="0.9373 0.2667 0.2667 1" group="3" contype="1" conaffinity="1" type="mesh" mesh="hand3_v1_L_little_ip_link" />
                                </body>
                              </body>
                            </body>
                          </body>
                        </body>
                      </body>
                    </body>
                  </body>
                </body>
              </body>
            </body>
          </body>
          <body name="R_shoulder_pitch_link" pos="-0.0046 0.34864 0.15387" quat="0.0616249 0.704415 0.7044172 -0.0616299">
            <joint name="R_shoulder_pitch_joint" type="hinge" axis="0 0 1" limited="true" range="-2.8623 2.8623" damping="0" frictionloss="0"/>
            <inertial pos="-0.0000887 0.0050444 -0.0526234" mass="0.9827294" fullinertia="0.0011778 0.0011244 0.0009029 -0.0000052 -0.0000046 0.0000315"/>
            <geom pos="0 0 0" group="1" contype="0" conaffinity="0" material="R_shoulder_pitch_link_mat" type="mesh" mesh="s2_R_shoulder_pitch_link" />
            <geom pos="0 0 0" rgba="0.9373 0.2667 0.2667 1" group="3" contype="1" conaffinity="1" type="mesh" mesh="s2_R_shoulder_pitch_link" />
            <body name="R_shoulder_roll_link" pos="0 0 -0.06" quat="0.7071055 -0.7071081 0 0">
              <joint name="R_shoulder_roll_joint" type="hinge" axis="0 0 1" limited="true" range="-1.885 0.1222" damping="0" frictionloss="0"/>
              <inertial pos="-0.0360914 0.0019662 0.0053449" mass="0.5433996" fullinertia="0.0012461 0.0019119 0.0014368 -0.0000187 -0.000109 0.000013"/>
              <geom pos="0 0 0" group="1" contype="0" conaffinity="0" material="R_shoulder_roll_link_mat" type="mesh" mesh="s2_R_shoulder_roll_link" />
              <geom pos="0 0 0" rgba="0.9373 0.2667 0.2667 1" group="3" contype="1" conaffinity="1" type="mesh" mesh="s2_R_shoulder_roll_link" />
              <body name="R_shoulder_yaw_link" pos="-0.083 0 0" quat="0.5049788 -0.4949693 -0.5049824 0.4949693">
                <joint name="R_shoulder_yaw_joint" type="hinge" axis="0 0 1" limited="true" range="-2.9322 2.9322" damping="0" frictionloss="0"/>
                <inertial pos="-0.0090557 -0.0029797 0.1286266" mass="1.9964922" fullinertia="0.0156407 0.0157507 0.0021093 -0.0000494 0.0015722 0.000468"/>
                <geom pos="0 0 0" group="1" contype="0" conaffinity="0" material="R_shoulder_yaw_link_mat" type="mesh" mesh="s2_R_shoulder_yaw_link" />
                <geom pos="0 0 0" rgba="0.9373 0.2667 0.2667 1" group="3" contype="1" conaffinity="1" type="mesh" mesh="s2_R_shoulder_yaw_link" />
                <body name="R_elbow_roll_link" pos="-0.019989 -0.0004003 0.213" quat="0.70707 -0.7070726 -0.0070791 0.0070791">
                  <joint name="R_elbow_roll_joint" type="hinge" axis="0 0 1" limited="true" range="-2.6529 0.0349" damping="0" frictionloss="0"/>
                  <inertial pos="0.0083606 -0.0579 -0.0006582" mass="0.6833698" fullinertia="0.0025998 0.0014326 0.0022487 0.0002975 -0.000005 0.0000264"/>
                  <geom pos="0 0 0" group="1" contype="0" conaffinity="0" material="R_elbow_roll_link_mat" type="mesh" mesh="s2_R_elbow_roll_link" />
                  <geom pos="0 0 0" rgba="0.9373 0.2667 0.2667 1" group="3" contype="1" conaffinity="1" type="mesh" mesh="s2_R_elbow_roll_link" />
                  <body name="R_elbow_yaw_link" pos="0.019993 -0.10368 0" quat="0.7071055 0.7071081 0 0">
                    <joint name="R_elbow_yaw_joint" type="hinge" axis="0 0 1" limited="true" range="-2.9322 2.9322" damping="0" frictionloss="0"/>
                    <inertial pos="-0.0009741 -0.0001792 0.0457771" mass="0.8745749" fullinertia="0.0014384 0.00164 0.0008758 0.0000039 0.0000522 -0.0000007"/>
                    <geom pos="0 0 0" group="1" contype="0" conaffinity="0" material="R_elbow_yaw_link_mat" type="mesh" mesh="s2_R_elbow_yaw_link" />
                    <geom pos="0 0 0" rgba="0.9373 0.2667 0.2667 1" group="3" contype="1" conaffinity="1" type="mesh" mesh="s2_R_elbow_yaw_link" />
                    <body name="R_wrist_pitch_link" pos="0 0 0.11832" quat="-0.0000026 0.7071055 -0.0000026 -0.7071081">
                      <joint name="R_wrist_pitch_joint" type="hinge" axis="0 0 1" limited="true" range="-1.658 1.658" damping="0" frictionloss="0"/>
                      <inertial pos="-0.0384446 0.0048559 0.004772" mass="1.3144509" fullinertia="0.0009004 0.0027314 0.0027358 0.000219 -0.0002271 0.0000305"/>
                      <geom pos="0 0 0" group="1" contype="0" conaffinity="0" material="R_wrist_pitch_link_mat" type="mesh" mesh="s2_R_wrist_pitch_link" />
                      <geom pos="0 0 0" rgba="0.9373 0.2667 0.2667 1" group="3" contype="1" conaffinity="1" type="mesh" mesh="s2_R_wrist_pitch_link" />
                      <body name="R_wrist_roll_link" pos="-0.076 0 0" quat="0.5 -0.5000018 0.4999982 0.5">
                        <joint name="R_wrist_roll_joint" type="hinge" axis="0 0 1" limited="true" range="-2.0245 2.0245" damping="0" frictionloss="0"/>
                        <inertial pos="0.0000046 0.0170562 0.0007487" mass="0.1521023" fullinertia="0.0002736 0.0002155 0.0001102 0 0 0.0000077"/>
                        <geom pos="0 0 0" group="1" contype="0" conaffinity="0" material="R_wrist_roll_link_mat" type="mesh" mesh="s2_R_wrist_roll_link" />
                        <geom pos="0 0 0" rgba="0.9373 0.2667 0.2667 1" group="3" contype="1" conaffinity="1" type="mesh" mesh="s2_R_wrist_roll_link" />
                        <body name="R_sixforce_link" pos="0 0.07712 0" quat="0.4999982 -0.5 0.5 0.5000018">
                          <inertial pos="-0.0001861 -0.0000021 -0.0110656" mass="0.17" fullinertia="0.0000357 0.0000503 0.0000613 0.0000002 0.0000008 -0.0000001"/>
                          <geom pos="0 0 0" group="1" contype="0" conaffinity="0" material="R_sixforce_link_mat" type="mesh" mesh="s2_R_sixforce_link" />
                          <geom pos="0 0 0" rgba="0.9373 0.2667 0.2667 1" group="3" contype="1" conaffinity="1" type="mesh" mesh="s2_R_sixforce_link" />
                          <body name="hand3_v1_right" pos="0 0 0" quat="0 0 0 1">
                            <inertial pos="0.0006593 -0.0006466 0.0222316" mass="0.052387" fullinertia="0.0000172 0.0000368 0.0000401 -0.0000003 -0.0000004 0.0000002"/>
                            <geom pos="0 0 0" group="1" contype="0" conaffinity="0" material="hand3_v1_right_mat" type="mesh" mesh="hand3_v1_R_hand_base_link" />
                            <geom pos="0 0 0" rgba="0.9373 0.2667 0.2667 1" group="3" contype="1" conaffinity="1" type="mesh" mesh="hand3_v1_R_hand_base_link" />
                            <body name="hand3_v1_right_R_palm_link" pos="0.000357 -0.013196 0.099778" quat="0.4999982 0.5 -0.5 0.5000018">
                              <inertial pos="-0.0093887 0.002217 -0.0117814" mass="0.3822359" fullinertia="0.0002277 0.0003527 0.0005035 0.0000017 0 0.0000132"/>
                              <geom pos="0 0 0" group="1" contype="0" conaffinity="0" material="hand3_v1_right_R_palm_link_mat" type="mesh" mesh="hand3_v1_R_palm_link" />
                              <geom pos="0 0 0" rgba="0.9373 0.2667 0.2667 1" group="3" contype="1" conaffinity="1" type="mesh" mesh="hand3_v1_R_palm_link" />
                              <body name="hand3_v1_right_R_thumb_cmp_link" pos="-0.048578 -0.028956 -0.0073648" quat="0.6487046 0.2813912 -0.6487067 -0.2813912">
                                <joint name="hand3_v1_right_R_thumb_cmp_joint" type="hinge" axis="0 0 1" limited="true" range="0 0.96" damping="0" frictionloss="0"/>
                                <inertial pos="0.0056308 0.00075 -0.0043585" mass="0.0151103" fullinertia="0.0000009 0.000001 0.0000011 -0.0000001 0.0000003 0"/>
                                <geom pos="0 0 0" group="1" contype="0" conaffinity="0" material="hand3_v1_right_R_thumb_cmp_link_mat" type="mesh" mesh="hand3_v1_R_thumb_cmp_link" />
                                <geom pos="0 0 0" rgba="0.9373 0.2667 0.2667 1" group="3" contype="1" conaffinity="1" type="mesh" mesh="hand3_v1_R_thumb_cmp_link" />
                                <body name="hand3_v1_right_R_thumb_mpp_link" pos="0.012 0.0010557 -0.010045" quat="0.743137 -0.6691393 -0.0000519 -0.0000576">
                                  <joint name="hand3_v1_right_R_thumb_mpp_joint" type="hinge" axis="0 0 1" limited="true" range="0 1.04" damping="0" frictionloss="0"/>
                                  <inertial pos="0.0361842 -0.0019502 0.000077" mass="0.067412" fullinertia="0.0000064 0.000033 0.0000327 -0.0000027 0 0"/>
                                  <geom pos="0 0 0" group="1" contype="0" conaffinity="0" material="hand3_v1_right_R_thumb_mpp_link_mat" type="mesh" mesh="hand3_v1_R_thumb_mpp_link" />
                                  <geom pos="0 0 0" rgba="0.9373 0.2667 0.2667 1" group="3" contype="1" conaffinity="1" type="mesh" mesh="hand3_v1_R_thumb_mpp_link" />
                                  <body name="hand3_v1_right_R_thumb_ip_link" pos="0.075 0 0" quat="0.9999818 0 0 0.006041">
                                    <joint name="hand3_v1_right_R_thumb_ip_joint" type="hinge" axis="0 0 1" limited="true" range="0 1.05" damping="0" frictionloss="0"/>
                                    <inertial pos="0.0135371 0.0041693 -0.0000061" mass="0.0173112" fullinertia="0.000001 0.0000019 0.0000018 -0.0000001 0 0"/>
                                    <geom pos="0 0 0" group="1" contype="0" conaffinity="0" material="hand3_v1_right_R_thumb_ip_link_mat" type="mesh" mesh="hand3_v1_R_thumb_ip_link" />
                                    <geom pos="0 0 0" rgba="0.9373 0.2667 0.2667 1" group="3" contype="1" conaffinity="1" type="mesh" mesh="hand3_v1_R_thumb_ip_link" />
                                  </body>
                                </body>
                              </body>
                              <body name="hand3_v1_right_R_index_mpp_link" pos="0.041818 -0.03077 -0.011696" quat="0.7048125 0.7035312 -0.0710329 0.0568992">
                                <joint name="hand3_v1_right_R_index_mpp_joint" type="hinge" axis="0 0 1" limited="true" range="0 1.46" damping="0" frictionloss="0"/>
                                <inertial pos="0.0152531 -0.0018168 -0.0001521" mass="0.0147008" diaginertia="0.0000009 0.0000036 0.0000035"/>
                                <geom pos="0 0 0" group="1" contype="0" conaffinity="0" material="hand3_v1_right_R_index_mpp_link_mat" type="mesh" mesh="hand3_v1_R_index_mpp_link" />
                                <geom pos="0 0 0" rgba="0.9373 0.2667 0.2667 1" group="3" contype="1" conaffinity="1" type="mesh" mesh="hand3_v1_R_index_mpp_link" />
                                <body name="hand3_v1_right_R_index_ip_link" pos="0.0388 0 0" quat="0.9999737 0 0 -0.0072544">
                                  <joint name="hand3_v1_right_R_index_ip_joint" type="hinge" axis="0 0 1" limited="true" range="0 1.62" damping="0" frictionloss="0"/>
                                  <inertial pos="0.0168086 -0.0011753 0" mass="0.0133493" fullinertia="0.0000004 0.0000026 0.0000026 -0.0000003 0 0"/>
                                  <geom pos="0 0 0" group="1" contype="0" conaffinity="0" material="hand3_v1_right_R_index_ip_link_mat" type="mesh" mesh="hand3_v1_R_index_ip_link" />
                                  <geom pos="0 0 0" rgba="0.9373 0.2667 0.2667 1" group="3" contype="1" conaffinity="1" type="mesh" mesh="hand3_v1_R_index_ip_link" />
                                </body>
                              </body>
                              <body name="hand3_v1_right_R_middle_mpp_link" pos="0.042022 -0.011107 -0.011696" quat="0.7047763 0.7035728 -0.0571473 0.0707808">
                                <joint name="hand3_v1_right_R_middle_mpp_joint" type="hinge" axis="0 0 1" limited="true" range="0 1.46" damping="0" frictionloss="0"/>
                                <inertial pos="0.0147601 -0.0017148 -0.0001287" mass="0.0143021" diaginertia="0.0000009 0.0000034 0.0000034"/>
                                <geom pos="0 0 0" group="1" contype="0" conaffinity="0" material="hand3_v1_right_R_middle_mpp_link_mat" type="mesh" mesh="hand3_v1_R_middle_mpp_link" />
                                <geom pos="0 0 0" rgba="0.9373 0.2667 0.2667 1" group="3" contype="1" conaffinity="1" type="mesh" mesh="hand3_v1_R_middle_mpp_link" />
                                <body name="hand3_v1_right_R_middle_ip_link" pos="0.038807 0 0" quat="0.999935 0.0000584 -0.0096774 -0.0060326">
                                  <joint name="hand3_v1_right_R_middle_ip_joint" type="hinge" axis="0 0 1" limited="true" range="0 1.62" damping="0" frictionloss="0"/>
                                  <inertial pos="0.0177132 -0.0010967 -0.0000256" mass="0.0148881" fullinertia="0.0000005 0.0000034 0.0000034 -0.0000004 0 0"/>
                                  <geom pos="0 0 0" group="1" contype="0" conaffinity="0" material="hand3_v1_right_R_middle_ip_link_mat" type="mesh" mesh="hand3_v1_R_middle_ip_link" />
                                  <geom pos="0 0 0" rgba="0.9373 0.2667 0.2667 1" group="3" contype="1" conaffinity="1" type="mesh" mesh="hand3_v1_R_middle_ip_link" />
                                </body>
                              </body>
                              <body name="hand3_v1_right_R_ring_mpp_link" pos="0.041818 0.010057 -0.011696" quat="0.7035286 0.7048151 -0.0568989 0.0710331">
                                <joint name="hand3_v1_right_R_ring_mpp_joint" type="hinge" axis="0 0 1" limited="true" range="0 1.46" damping="0" frictionloss="0"/>
                                <inertial pos="0.0147595 -0.001715 -0.0001287" mass="0.0143021" diaginertia="0.0000009 0.0000034 0.0000034"/>
                                <geom pos="0 0 0" group="1" contype="0" conaffinity="0" material="hand3_v1_right_R_ring_mpp_link_mat" type="mesh" mesh="hand3_v1_R_ring_mpp_link" />
                                <geom pos="0 0 0" rgba="0.9373 0.2667 0.2667 1" group="3" contype="1" conaffinity="1" type="mesh" mesh="hand3_v1_R_ring_mpp_link" />
                                <body name="hand3_v1_right_R_ring_ip_link" pos="0.0388 0 0" quat="0.9999737 0 0 -0.0072544">
                                  <joint name="hand3_v1_right_R_ring_ip_joint" type="hinge" axis="0 0 1" limited="true" range="0 1.62" damping="0" frictionloss="0"/>
                                  <inertial pos="0.0161543 -0.0013024 -0.0000276" mass="0.0137479" fullinertia="0.0000004 0.0000028 0.0000028 -0.0000003 0 0"/>
                                  <geom pos="0 0 0" group="1" contype="0" conaffinity="0" material="hand3_v1_right_R_ring_ip_link_mat" type="mesh" mesh="hand3_v1_R_ring_ip_link" />
                                  <geom pos="0 0 0" rgba="0.9373 0.2667 0.2667 1" group="3" contype="1" conaffinity="1" type="mesh" mesh="hand3_v1_R_ring_ip_link" />
                                </body>
                              </body>
                              <body name="hand3_v1_right_R_little_mpp_link" pos="0.041203 0.030462 -0.011696" quat="0.7027803 0.7053506 -0.0498226 0.07809">
                                <joint name="hand3_v1_right_R_little_mpp_joint" type="hinge" axis="0 0 1" limited="true" range="0 1.46" damping="0" frictionloss="0"/>
                                <inertial pos="0.0147588 -0.0017151 -0.0001287" mass="0.0143021" diaginertia="0.0000009 0.0000034 0.0000034"/>
                                <geom pos="0 0 0" group="1" contype="0" conaffinity="0" material="hand3_v1_right_R_little_mpp_link_mat" type="mesh" mesh="hand3_v1_R_little_mpp_link" />
                                <geom pos="0 0 0" rgba="0.9373 0.2667 0.2667 1" group="3" contype="1" conaffinity="1" type="mesh" mesh="hand3_v1_R_little_mpp_link" />
                                <body name="hand3_v1_right_R_little_ip_link" pos="0.0388 0 0" quat="0.9999737 0 0 -0.0072544">
                                  <joint name="hand3_v1_right_R_little_ip_joint" type="hinge" axis="0 0 1" limited="true" range="0 1.62" damping="0" frictionloss="0"/>
                                  <inertial pos="0.0130333 -0.0014344 -0.0000295" mass="0.0117927" fullinertia="0.0000003 0.0000018 0.0000018 -0.0000002 0 0"/>
                                  <geom pos="0 0 0" group="1" contype="0" conaffinity="0" material="hand3_v1_right_R_little_ip_link_mat" type="mesh" mesh="hand3_v1_R_little_ip_link" />
                                  <geom pos="0 0 0" rgba="0.9373 0.2667 0.2667 1" group="3" contype="1" conaffinity="1" type="mesh" mesh="hand3_v1_R_little_ip_link" />
                                </body>
                              </body>
                            </body>
                          </body>
                        </body>
                      </body>
                    </body>
                  </body>
                </body>
              </body>
            </body>
          </body>
        </body>
      </body>
      <body name="L_hip_roll_link" pos="0 0.105 0" quat="0.7093998 0 0.7048063 0">
        <joint name="L_hip_roll_joint" type="hinge" axis="0 0 1" limited="true" range="-0.4363 0.7853" damping="0" frictionloss="0"/>
        <inertial pos="0.0092362 0.0006846 -0.0076246" mass="1.3210575" fullinertia="0.001866 0.0017359 0.0011634 0.0000152 -0.000098 0.0000252"/>
        <geom pos="0 0 0" group="1" contype="0" conaffinity="0" material="L_hip_roll_link_mat" type="mesh" mesh="s2_L_hip_roll_link" />
        <geom pos="0 0 0" rgba="0.9373 0.2667 0.2667 1" group="3" contype="1" conaffinity="1" type="mesh" mesh="s2_L_hip_roll_link" />
        <body name="L_hip_yaw_link" pos="0 0 0" quat="-0.0000038 0.7071064 0.0000013 0.7071071">
          <joint name="L_hip_yaw_joint" type="hinge" axis="0 0 1" limited="true" range="-0.7853 1.0471" damping="0" frictionloss="0"/>
          <inertial pos="0.0002396 0.0039636 0.1156868" mass="2.2890973" fullinertia="0.0043044 0.0048929 0.0036277 0.000004 -0.0000092 -0.000051"/>
          <geom pos="0 0 0" group="1" contype="0" conaffinity="0" material="L_hip_yaw_link_mat" type="mesh" mesh="s2_L_hip_yaw_link" />
          <geom pos="0 0 0" rgba="0.9373 0.2667 0.2667 1" group="3" contype="1" conaffinity="1" type="mesh" mesh="s2_L_hip_yaw_link" />
          <body name="L_hip_pitch_link" pos="0 0 0.122" quat="0.7071055 -0.7071081 0 0">
            <joint name="L_hip_pitch_joint" type="hinge" axis="0 0 1" limited="true" range="-0.349 1.9198" damping="0" frictionloss="0"/>
            <inertial pos="0.0018469 -0.1559023 -0.0026939" mass="4.1506052" fullinertia="0.0429205 0.0099854 0.0427849 0.00183 0.0000639 -0.001123"/>
            <geom pos="0 0 0" group="1" contype="0" conaffinity="0" material="L_hip_pitch_link_mat" type="mesh" mesh="s2_L_hip_pitch_link" />
            <geom pos="0 0 0" rgba="0.9373 0.2667 0.2667 1" group="3" contype="1" conaffinity="1" type="mesh" mesh="s2_L_hip_pitch_link" />
            <body name="L_knee_pitch_link" pos="0 -0.36 0">
              <joint name="L_knee_pitch_joint" type="hinge" axis="0 0 1" limited="true" range="-2.2689 0.0872" damping="0" frictionloss="0"/>
              <inertial pos="-0.0010047 -0.1595464 0.0010045" mass="3.8268754" fullinertia="0.0340689 0.0048648 0.0348156 -0.000889 -0.0000685 -0.000151"/>
              <geom pos="0 0 0" group="1" contype="0" conaffinity="0" material="L_knee_pitch_link_mat" type="mesh" mesh="s2_L_knee_pitch_link" />
              <geom pos="0 0 0" rgba="0.9373 0.2667 0.2667 1" group="3" contype="1" conaffinity="1" type="mesh" mesh="s2_L_knee_pitch_link" />
              <body name="L_ankle_pitch_link" pos="0 -0.37 0" quat="0.9999948 0 0 -0.0032383">
                <joint name="L_ankle_pitch_joint" type="hinge" axis="0 0 1" limited="true" range="-0.5235 1.0471" damping="0" frictionloss="0"/>
                <inertial pos="0 0 0" mass="0.0659137" diaginertia="0.0000109 0.0000184 0.0000109"/>
                <geom pos="0 0 0" group="1" contype="0" conaffinity="0" material="L_ankle_pitch_link_mat" type="mesh" mesh="s2_L_ankle_pitch_link" />
                <geom pos="0 0 0" rgba="0.9373 0.2667 0.2667 1" group="3" contype="1" conaffinity="1" type="mesh" mesh="s2_L_ankle_pitch_link" />
                <body name="L_ankle_roll_link" pos="0 0 0" quat="0.4983705 0.4983724 0.5016242 0.5016224">
                  <joint name="L_ankle_roll_joint" type="hinge" axis="0 0 1" limited="true" range="-0.5235 0.5235" damping="0" frictionloss="0"/>
                  <inertial pos="-0.0309979 -0.000273 0.0239737" mass="0.7830616" fullinertia="0.0032684 0.0028805 0.0007011 -0.0000022 0.000163 -0.0000078"/>
                  <geom pos="0 0 0" group="1" contype="0" conaffinity="0" material="L_ankle_roll_link_mat" type="mesh" mesh="s2_L_ankle_roll_link" />
                  <geom pos="0 0 0" rgba="0.9373 0.2667 0.2667 1" group="3" contype="1" conaffinity="1" type="mesh" mesh="s2_L_ankle_roll_link" />
                </body>
              </body>
            </body>
          </body>
        </body>
      </body>
      <body name="R_hip_roll_link" pos="0 -0.105 0" quat="0.7093998 0 0.7048063 0">
        <joint name="R_hip_roll_joint" type="hinge" axis="0 0 1" limited="true" range="-0.7853 0.4363" damping="0" frictionloss="0"/>
        <inertial pos="0.0092362 0.0006846 -0.0076246" mass="1.3210575" fullinertia="0.001866 0.0017359 0.0011634 0.0000152 -0.000098 0.0000252"/>
        <geom pos="0 0 0" group="1" contype="0" conaffinity="0" material="R_hip_roll_link_mat" type="mesh" mesh="s2_R_hip_roll_link" />
        <geom pos="0 0 0" rgba="0.9373 0.2667 0.2667 1" group="3" contype="1" conaffinity="1" type="mesh" mesh="s2_R_hip_roll_link" />
        <body name="R_hip_yaw_link" pos="0 0 0" quat="-0.0000039 0.7071067 0.0000013 0.7071069">
          <joint name="R_hip_yaw_joint" type="hinge" axis="0 0 1" limited="true" range="-1.0471 0.7853" damping="0" frictionloss="0"/>
          <inertial pos="0.0002396 0.0039636 0.1156868" mass="2.2890973" fullinertia="0.0043044 0.0048929 0.0036277 0.000004 -0.0000092 -0.000051"/>
          <geom pos="0 0 0" group="1" contype="0" conaffinity="0" material="R_hip_yaw_link_mat" type="mesh" mesh="s2_R_hip_yaw_link" />
          <geom pos="0 0 0" rgba="0.9373 0.2667 0.2667 1" group="3" contype="1" conaffinity="1" type="mesh" mesh="s2_R_hip_yaw_link" />
          <body name="R_hip_pitch_link" pos="0 0 0.122" quat="0.7071055 -0.7071081 0 0">
            <joint name="R_hip_pitch_joint" type="hinge" axis="0 0 1" limited="true" range="-0.349 1.9198" damping="0" frictionloss="0"/>
            <inertial pos="0.0015213 -0.1556053 0.0027829" mass="4.1557525" fullinertia="0.0428739 0.0100023 0.0427171 0.0019094 -0.0000843 0.00113"/>
            <geom pos="0 0 0" group="1" contype="0" conaffinity="0" material="R_hip_pitch_link_mat" type="mesh" mesh="s2_R_hip_pitch_link" />
            <geom pos="0 0 0" rgba="0.9373 0.2667 0.2667 1" group="3" contype="1" conaffinity="1" type="mesh" mesh="s2_R_hip_pitch_link" />
            <body name="R_knee_pitch_link" pos="0 -0.36 0">
              <joint name="R_knee_pitch_joint" type="hinge" axis="0 0 1" limited="true" range="-2.2689 0.0872" damping="0" frictionloss="0"/>
              <inertial pos="-0.0010047 -0.1595464 0.0010045" mass="3.8268754" fullinertia="0.0340689 0.0048648 0.0348156 -0.000889 -0.0000685 -0.000151"/>
              <geom pos="0 0 0" group="1" contype="0" conaffinity="0" material="R_knee_pitch_link_mat" type="mesh" mesh="s2_R_knee_pitch_link" />
              <geom pos="0 0 0" rgba="0.9373 0.2667 0.2667 1" group="3" contype="1" conaffinity="1" type="mesh" mesh="s2_R_knee_pitch_link" />
              <body name="R_ankle_pitch_link" pos="0 -0.37 0">
                <joint name="R_ankle_pitch_joint" type="hinge" axis="0 0 1" limited="true" range="-0.5235 1.0471" damping="0" frictionloss="0"/>
                <inertial pos="0 0 0" mass="0.0659137" diaginertia="0.0000109 0.0000184 0.0000109"/>
                <geom pos="0 0 0" group="1" contype="0" conaffinity="0" material="R_ankle_pitch_link_mat" type="mesh" mesh="s2_R_ankle_pitch_link" />
                <geom pos="0 0 0" rgba="0.9373 0.2667 0.2667 1" group="3" contype="1" conaffinity="1" type="mesh" mesh="s2_R_ankle_pitch_link" />
                <body name="R_ankle_roll_link" pos="0 0 0" quat="0.4999982 0.5 0.5000018 0.5">
                  <joint name="R_ankle_roll_joint" type="hinge" axis="0 0 1" limited="true" range="-0.5235 0.5235" damping="0" frictionloss="0"/>
                  <inertial pos="-0.0309981 0.0002657 0.0239511" mass="0.783156" fullinertia="0.0032686 0.0028805 0.0007013 0.0000022 0.000164 0.0000075"/>
                  <geom pos="0 0 0" group="1" contype="0" conaffinity="0" material="R_ankle_roll_link_mat" type="mesh" mesh="s2_R_ankle_roll_link" />
                  <geom pos="0 0 0" rgba="0.9373 0.2667 0.2667 1" group="3" contype="1" conaffinity="1" type="mesh" mesh="s2_R_ankle_roll_link" />
                </body>
              </body>
            </body>
          </body>
        </body>
      </body>
    </body>
  </worldbody>
  <actuator>
    <motor name="waist_yaw_joint_motor" joint="waist_yaw_joint" gear="1" ctrllimited="true" ctrlrange="-85 85" />
    <motor name="waist_pitch_joint_motor" joint="waist_pitch_joint" gear="1" ctrllimited="true" ctrlrange="-265 265" />
    <motor name="head_yaw_joint_motor" joint="head_yaw_joint" gear="1" ctrllimited="true" ctrlrange="-4.5 4.5" />
    <motor name="head_pitch_joint_motor" joint="head_pitch_joint" gear="1" ctrllimited="true" ctrlrange="-4.5 4.5" />
    <motor name="L_shoulder_pitch_joint_motor" joint="L_shoulder_pitch_joint" gear="1" ctrllimited="true" ctrlrange="-80 80" />
    <motor name="L_shoulder_roll_joint_motor" joint="L_shoulder_roll_joint" gear="1" ctrllimited="true" ctrlrange="-80 80" />
    <motor name="L_shoulder_yaw_joint_motor" joint="L_shoulder_yaw_joint" gear="1" ctrllimited="true" ctrlrange="-45 45" />
    <motor name="L_elbow_roll_joint_motor" joint="L_elbow_roll_joint" gear="1" ctrllimited="true" ctrlrange="-45 45" />
    <motor name="L_elbow_yaw_joint_motor" joint="L_elbow_yaw_joint" gear="1" ctrllimited="true" ctrlrange="-20 20" />
    <motor name="L_wrist_pitch_joint_motor" joint="L_wrist_pitch_joint" gear="1" ctrllimited="true" ctrlrange="-20 20" />
    <motor name="L_wrist_roll_joint_motor" joint="L_wrist_roll_joint" gear="1" ctrllimited="true" ctrlrange="-20 20" />
    <motor name="R_shoulder_pitch_joint_motor" joint="R_shoulder_pitch_joint" gear="1" ctrllimited="true" ctrlrange="-80 80" />
    <motor name="R_shoulder_roll_joint_motor" joint="R_shoulder_roll_joint" gear="1" ctrllimited="true" ctrlrange="-80 80" />
    <motor name="R_shoulder_yaw_joint_motor" joint="R_shoulder_yaw_joint" gear="1" ctrllimited="true" ctrlrange="-45 45" />
    <motor name="R_elbow_roll_joint_motor" joint="R_elbow_roll_joint" gear="1" ctrllimited="true" ctrlrange="-45 45" />
    <motor name="R_elbow_yaw_joint_motor" joint="R_elbow_yaw_joint" gear="1" ctrllimited="true" ctrlrange="-20 20" />
    <motor name="R_wrist_pitch_joint_motor" joint="R_wrist_pitch_joint" gear="1" ctrllimited="true" ctrlrange="-20 20" />
    <motor name="R_wrist_roll_joint_motor" joint="R_wrist_roll_joint" gear="1" ctrllimited="true" ctrlrange="-20 20" />
    <motor name="L_hip_roll_joint_motor" joint="L_hip_roll_joint" gear="1" ctrllimited="true" ctrlrange="-225 225" />
    <motor name="L_hip_yaw_joint_motor" joint="L_hip_yaw_joint" gear="1" ctrllimited="true" ctrlrange="-65 65" />
    <motor name="L_hip_pitch_joint_motor" joint="L_hip_pitch_joint" gear="1" ctrllimited="true" ctrlrange="-225 225" />
    <motor name="L_knee_pitch_joint_motor" joint="L_knee_pitch_joint" gear="1" ctrllimited="true" ctrlrange="-225 225" />
    <motor name="L_ankle_pitch_joint_motor" joint="L_ankle_pitch_joint" gear="1" ctrllimited="true" ctrlrange="-65 65" />
    <motor name="L_ankle_roll_joint_motor" joint="L_ankle_roll_joint" gear="1" ctrllimited="true" ctrlrange="-65 65" />
    <motor name="R_hip_roll_joint_motor" joint="R_hip_roll_joint" gear="1" ctrllimited="true" ctrlrange="-225 225" />
    <motor name="R_hip_yaw_joint_motor" joint="R_hip_yaw_joint" gear="1" ctrllimited="true" ctrlrange="-65 65" />
    <motor name="R_hip_pitch_joint_motor" joint="R_hip_pitch_joint" gear="1" ctrllimited="true" ctrlrange="-225 225" />
    <motor name="R_knee_pitch_joint_motor" joint="R_knee_pitch_joint" gear="1" ctrllimited="true" ctrlrange="-225 225" />
    <motor name="R_ankle_pitch_joint_motor" joint="R_ankle_pitch_joint" gear="1" ctrllimited="true" ctrlrange="-65 65" />
    <motor name="R_ankle_roll_joint_motor" joint="R_ankle_roll_joint" gear="1" ctrllimited="true" ctrlrange="-65 65" />
    <motor name="hand3_v1_left_L_thumb_cmp_joint_motor" joint="hand3_v1_left_L_thumb_cmp_joint" gear="1" ctrllimited="true" ctrlrange="-1.35 1.35" />
    <motor name="hand3_v1_left_L_thumb_mpp_joint_motor" joint="hand3_v1_left_L_thumb_mpp_joint" gear="1" ctrllimited="true" ctrlrange="-1.35 1.35" />
    <motor name="hand3_v1_left_L_thumb_ip_joint_motor" joint="hand3_v1_left_L_thumb_ip_joint" gear="1" ctrllimited="true" ctrlrange="-1.35 1.35" />
    <motor name="hand3_v1_left_L_index_mpp_joint_motor" joint="hand3_v1_left_L_index_mpp_joint" gear="1" ctrllimited="true" ctrlrange="-1.35 1.35" />
    <motor name="hand3_v1_left_L_index_ip_joint_motor" joint="hand3_v1_left_L_index_ip_joint" gear="1" ctrllimited="true" ctrlrange="-1.35 1.35" />
    <motor name="hand3_v1_left_L_middle_mpp_joint_motor" joint="hand3_v1_left_L_middle_mpp_joint" gear="1" ctrllimited="true" ctrlrange="-1.35 1.35" />
    <motor name="hand3_v1_left_L_middle_ip_joint_motor" joint="hand3_v1_left_L_middle_ip_joint" gear="1" ctrllimited="true" ctrlrange="-1.35 1.35" />
    <motor name="hand3_v1_left_L_ring_mpp_joint_motor" joint="hand3_v1_left_L_ring_mpp_joint" gear="1" ctrllimited="true" ctrlrange="-1.35 1.35" />
    <motor name="hand3_v1_left_L_ring_ip_joint_motor" joint="hand3_v1_left_L_ring_ip_joint" gear="1" ctrllimited="true" ctrlrange="-1.35 1.35" />
    <motor name="hand3_v1_left_L_little_mpp_joint_motor" joint="hand3_v1_left_L_little_mpp_joint" gear="1" ctrllimited="true" ctrlrange="-1.35 1.35" />
    <motor name="hand3_v1_left_L_little_ip_joint_motor" joint="hand3_v1_left_L_little_ip_joint" gear="1" ctrllimited="true" ctrlrange="-1.35 1.35" />
    <motor name="hand3_v1_right_R_thumb_cmp_joint_motor" joint="hand3_v1_right_R_thumb_cmp_joint" gear="1" ctrllimited="true" ctrlrange="-1.35 1.35" />
    <motor name="hand3_v1_right_R_thumb_mpp_joint_motor" joint="hand3_v1_right_R_thumb_mpp_joint" gear="1" ctrllimited="true" ctrlrange="-1.35 1.35" />
    <motor name="hand3_v1_right_R_thumb_ip_joint_motor" joint="hand3_v1_right_R_thumb_ip_joint" gear="1" ctrllimited="true" ctrlrange="-1.35 1.35" />
    <motor name="hand3_v1_right_R_index_mpp_joint_motor" joint="hand3_v1_right_R_index_mpp_joint" gear="1" ctrllimited="true" ctrlrange="-1.35 1.35" />
    <motor name="hand3_v1_right_R_index_ip_joint_motor" joint="hand3_v1_right_R_index_ip_joint" gear="1" ctrllimited="true" ctrlrange="-1.35 1.35" />
    <motor name="hand3_v1_right_R_middle_mpp_joint_motor" joint="hand3_v1_right_R_middle_mpp_joint" gear="1" ctrllimited="true" ctrlrange="-1.35 1.35" />
    <motor name="hand3_v1_right_R_middle_ip_joint_motor" joint="hand3_v1_right_R_middle_ip_joint" gear="1" ctrllimited="true" ctrlrange="-1.35 1.35" />
    <motor name="hand3_v1_right_R_ring_mpp_joint_motor" joint="hand3_v1_right_R_ring_mpp_joint" gear="1" ctrllimited="true" ctrlrange="-1.35 1.35" />
    <motor name="hand3_v1_right_R_ring_ip_joint_motor" joint="hand3_v1_right_R_ring_ip_joint" gear="1" ctrllimited="true" ctrlrange="-1.35 1.35" />
    <motor name="hand3_v1_right_R_little_mpp_joint_motor" joint="hand3_v1_right_R_little_mpp_joint" gear="1" ctrllimited="true" ctrlrange="-1.35 1.35" />
    <motor name="hand3_v1_right_R_little_ip_joint_motor" joint="hand3_v1_right_R_little_ip_joint" gear="1" ctrllimited="true" ctrlrange="-1.35 1.35" />
  </actuator>
</mujoco>